<?xml version="1.0" ?>
<!-- =================================================================================== -->
<!-- |    This document was autogenerated by xacro from src/arm_assembly_description/urdf/arm_assembly.xacro | -->
<!-- |    EDITING THIS FILE BY HAND IS NOT RECOMMENDED                                 | -->
<!-- =================================================================================== -->
<robot name="arm_assembly">
  <material name="silver">
    <color rgba="0.700 0.700 0.700 1.000"/>
  </material>
  <transmission name="shoulder_flexion_extension_tran">
    <type>transmission_interface/SimpleTransmission</type>
    <joint name="shoulder_flexion_extension">
      <hardwareInterface>hardware_interface/EffortJointInterface</hardwareInterface>
    </joint>
    <actuator name="shoulder_flexion_extension_actr">
      <hardwareInterface>hardware_interface/EffortJointInterface</hardwareInterface>
      <mechanicalReduction>1</mechanicalReduction>
    </actuator>
  </transmission>
  <transmission name="shoulder_abduction_adduction_tran">
    <type>transmission_interface/SimpleTransmission</type>
    <joint name="shoulder_abduction_adduction">
      <hardwareInterface>hardware_interface/EffortJointInterface</hardwareInterface>
    </joint>
    <actuator name="shoulder_abduction_adduction_actr">
      <hardwareInterface>hardware_interface/EffortJointInterface</hardwareInterface>
      <mechanicalReduction>1</mechanicalReduction>
    </actuator>
  </transmission>
  <transmission name="shoulder_rotation_tran">
    <type>transmission_interface/SimpleTransmission</type>
    <joint name="shoulder_rotation">
      <hardwareInterface>hardware_interface/EffortJointInterface</hardwareInterface>
    </joint>
    <actuator name="shoulder_rotation_actr">
      <hardwareInterface>hardware_interface/EffortJointInterface</hardwareInterface>
      <mechanicalReduction>1</mechanicalReduction>
    </actuator>
  </transmission>
  <transmission name="elbow_flexion_extension_tran">
    <type>transmission_interface/SimpleTransmission</type>
    <joint name="elbow_flexion_extension">
      <hardwareInterface>hardware_interface/EffortJointInterface</hardwareInterface>
    </joint>
    <actuator name="elbow_flexion_extension_actr">
      <hardwareInterface>hardware_interface/EffortJointInterface</hardwareInterface>
      <mechanicalReduction>1</mechanicalReduction>
    </actuator>
  </transmission>
  <transmission name="forearm_rotation_tran">
    <type>transmission_interface/SimpleTransmission</type>
    <joint name="forearm_rotation">
      <hardwareInterface>hardware_interface/EffortJointInterface</hardwareInterface>
    </joint>
    <actuator name="forearm_rotation_actr">
      <hardwareInterface>hardware_interface/EffortJointInterface</hardwareInterface>
      <mechanicalReduction>1</mechanicalReduction>
    </actuator>
  </transmission>
  <transmission name="wrist_extension_tran">
    <type>transmission_interface/SimpleTransmission</type>
    <joint name="wrist_extension">
      <hardwareInterface>hardware_interface/EffortJointInterface</hardwareInterface>
    </joint>
    <actuator name="wrist_extension_actr">
      <hardwareInterface>hardware_interface/EffortJointInterface</hardwareInterface>
      <mechanicalReduction>1</mechanicalReduction>
    </actuator>
  </transmission>
  <transmission name="mcp_index_tran">
    <type>transmission_interface/SimpleTransmission</type>
    <joint name="mcp_index">
      <hardwareInterface>hardware_interface/EffortJointInterface</hardwareInterface>
    </joint>
    <actuator name="mcp_index_actr">
      <hardwareInterface>hardware_interface/EffortJointInterface</hardwareInterface>
      <mechanicalReduction>1</mechanicalReduction>
    </actuator>
  </transmission>
  <transmission name="pip_index_tran">
    <type>transmission_interface/SimpleTransmission</type>
    <joint name="pip_index">
      <hardwareInterface>hardware_interface/EffortJointInterface</hardwareInterface>
    </joint>
    <actuator name="pip_index_actr">
      <hardwareInterface>hardware_interface/EffortJointInterface</hardwareInterface>
      <mechanicalReduction>1</mechanicalReduction>
    </actuator>
  </transmission>
  <transmission name="dip_index_tran">
    <type>transmission_interface/SimpleTransmission</type>
    <joint name="dip_index">
      <hardwareInterface>hardware_interface/EffortJointInterface</hardwareInterface>
    </joint>
    <actuator name="dip_index_actr">
      <hardwareInterface>hardware_interface/EffortJointInterface</hardwareInterface>
      <mechanicalReduction>1</mechanicalReduction>
    </actuator>
  </transmission>
  <transmission name="mcp_middle_tran">
    <type>transmission_interface/SimpleTransmission</type>
    <joint name="mcp_middle">
      <hardwareInterface>hardware_interface/EffortJointInterface</hardwareInterface>
    </joint>
    <actuator name="mcp_middle_actr">
      <hardwareInterface>hardware_interface/EffortJointInterface</hardwareInterface>
      <mechanicalReduction>1</mechanicalReduction>
    </actuator>
  </transmission>
  <transmission name="pip_middle_tran">
    <type>transmission_interface/SimpleTransmission</type>
    <joint name="pip_middle">
      <hardwareInterface>hardware_interface/EffortJointInterface</hardwareInterface>
    </joint>
    <actuator name="pip_middle_actr">
      <hardwareInterface>hardware_interface/EffortJointInterface</hardwareInterface>
      <mechanicalReduction>1</mechanicalReduction>
    </actuator>
  </transmission>
  <transmission name="dip_middle_tran">
    <type>transmission_interface/SimpleTransmission</type>
    <joint name="dip_middle">
      <hardwareInterface>hardware_interface/EffortJointInterface</hardwareInterface>
    </joint>
    <actuator name="dip_middle_actr">
      <hardwareInterface>hardware_interface/EffortJointInterface</hardwareInterface>
      <mechanicalReduction>1</mechanicalReduction>
    </actuator>
  </transmission>
  <transmission name="mcp_ring_tran">
    <type>transmission_interface/SimpleTransmission</type>
    <joint name="mcp_ring">
      <hardwareInterface>hardware_interface/EffortJointInterface</hardwareInterface>
    </joint>
    <actuator name="mcp_ring_actr">
      <hardwareInterface>hardware_interface/EffortJointInterface</hardwareInterface>
      <mechanicalReduction>1</mechanicalReduction>
    </actuator>
  </transmission>
  <transmission name="pip_ring_tran">
    <type>transmission_interface/SimpleTransmission</type>
    <joint name="pip_ring">
      <hardwareInterface>hardware_interface/EffortJointInterface</hardwareInterface>
    </joint>
    <actuator name="pip_ring_actr">
      <hardwareInterface>hardware_interface/EffortJointInterface</hardwareInterface>
      <mechanicalReduction>1</mechanicalReduction>
    </actuator>
  </transmission>
  <transmission name="dip_ring_tran">
    <type>transmission_interface/SimpleTransmission</type>
    <joint name="dip_ring">
      <hardwareInterface>hardware_interface/EffortJointInterface</hardwareInterface>
    </joint>
    <actuator name="dip_ring_actr">
      <hardwareInterface>hardware_interface/EffortJointInterface</hardwareInterface>
      <mechanicalReduction>1</mechanicalReduction>
    </actuator>
  </transmission>
  <transmission name="mcp_pinky_tran">
    <type>transmission_interface/SimpleTransmission</type>
    <joint name="mcp_pinky">
      <hardwareInterface>hardware_interface/EffortJointInterface</hardwareInterface>
    </joint>
    <actuator name="mcp_pinky_actr">
      <hardwareInterface>hardware_interface/EffortJointInterface</hardwareInterface>
      <mechanicalReduction>1</mechanicalReduction>
    </actuator>
  </transmission>
  <transmission name="pip_pinky_tran">
    <type>transmission_interface/SimpleTransmission</type>
    <joint name="pip_pinky">
      <hardwareInterface>hardware_interface/EffortJointInterface</hardwareInterface>
    </joint>
    <actuator name="pip_pinky_actr">
      <hardwareInterface>hardware_interface/EffortJointInterface</hardwareInterface>
      <mechanicalReduction>1</mechanicalReduction>
    </actuator>
  </transmission>
  <transmission name="dip_pinky_tran">
    <type>transmission_interface/SimpleTransmission</type>
    <joint name="dip_pinky">
      <hardwareInterface>hardware_interface/EffortJointInterface</hardwareInterface>
    </joint>
    <actuator name="dip_pinky_actr">
      <hardwareInterface>hardware_interface/EffortJointInterface</hardwareInterface>
      <mechanicalReduction>1</mechanicalReduction>
    </actuator>
  </transmission>
  <transmission name="cmc_thumb_tran">
    <type>transmission_interface/SimpleTransmission</type>
    <joint name="cmc_thumb">
      <hardwareInterface>hardware_interface/EffortJointInterface</hardwareInterface>
    </joint>
    <actuator name="cmc_thumb_actr">
      <hardwareInterface>hardware_interface/EffortJointInterface</hardwareInterface>
      <mechanicalReduction>1</mechanicalReduction>
    </actuator>
  </transmission>
  <transmission name="mcp_thumb_tran">
    <type>transmission_interface/SimpleTransmission</type>
    <joint name="mcp_thumb">
      <hardwareInterface>hardware_interface/EffortJointInterface</hardwareInterface>
    </joint>
    <actuator name="mcp_thumb_actr">
      <hardwareInterface>hardware_interface/EffortJointInterface</hardwareInterface>
      <mechanicalReduction>1</mechanicalReduction>
    </actuator>
  </transmission>
  <transmission name="ip_thumb_tran">
    <type>transmission_interface/SimpleTransmission</type>
    <joint name="ip_thumb">
      <hardwareInterface>hardware_interface/EffortJointInterface</hardwareInterface>
    </joint>
    <actuator name="ip_thumb_actr">
      <hardwareInterface>hardware_interface/EffortJointInterface</hardwareInterface>
      <mechanicalReduction>1</mechanicalReduction>
    </actuator>
  </transmission>
  <gazebo>
    <plugin filename="libgazebo_ros_control.so" name="control"/>
  </gazebo>
  <gazebo reference="base_link">
    <material>Gazebo/Silver</material>
    <mu1>0.2</mu1>
    <mu2>0.2</mu2>
    <selfCollide>true</selfCollide>
    <gravity>true</gravity>
  </gazebo>
  <gazebo reference="shoulder_link_1_v9_1">
    <material>Gazebo/Silver</material>
    <mu1>0.2</mu1>
    <mu2>0.2</mu2>
    <selfCollide>true</selfCollide>
  </gazebo>
  <gazebo reference="shoulder_link_2_v4_1">
    <material>Gazebo/Silver</material>
    <mu1>0.2</mu1>
    <mu2>0.2</mu2>
    <selfCollide>true</selfCollide>
  </gazebo>
  <gazebo reference="elbow_link_1_v6_1">
    <material>Gazebo/Silver</material>
    <mu1>0.2</mu1>
    <mu2>0.2</mu2>
    <selfCollide>true</selfCollide>
  </gazebo>
  <gazebo reference="elbow_link_2_v7_1">
    <material>Gazebo/Silver</material>
    <mu1>0.2</mu1>
    <mu2>0.2</mu2>
    <selfCollide>true</selfCollide>
  </gazebo>
  <gazebo reference="forearm_v8_1">
    <material>Gazebo/Silver</material>
    <mu1>0.2</mu1>
    <mu2>0.2</mu2>
    <selfCollide>true</selfCollide>
  </gazebo>
  <gazebo reference="PALM_GAVIN_1DoF_Hinge_v2_1">
    <material>Gazebo/Silver</material>
    <mu1>0.2</mu1>
    <mu2>0.2</mu2>
    <selfCollide>true</selfCollide>
  </gazebo>
  <gazebo reference="MCP_INDEX_v1_1">
    <material>Gazebo/Silver</material>
    <mu1>0.2</mu1>
    <mu2>0.2</mu2>
    <selfCollide>true</selfCollide>
  </gazebo>
  <gazebo reference="PIP_INDEX_v1_1">
    <material>Gazebo/Silver</material>
    <mu1>0.2</mu1>
    <mu2>0.2</mu2>
    <selfCollide>true</selfCollide>
  </gazebo>
  <gazebo reference="DIP_INDEX_v1_1">
    <material>Gazebo/Silver</material>
    <mu1>0.2</mu1>
    <mu2>0.2</mu2>
    <selfCollide>true</selfCollide>
  </gazebo>
  <gazebo reference="MCP_MIDDLE_v1_1">
    <material>Gazebo/Silver</material>
    <mu1>0.2</mu1>
    <mu2>0.2</mu2>
    <selfCollide>true</selfCollide>
  </gazebo>
  <gazebo reference="PIP_MIDDLE_v1_1">
    <material>Gazebo/Silver</material>
    <mu1>0.2</mu1>
    <mu2>0.2</mu2>
    <selfCollide>true</selfCollide>
  </gazebo>
  <gazebo reference="DIP_MIDDLE_v1_1">
    <material>Gazebo/Silver</material>
    <mu1>0.2</mu1>
    <mu2>0.2</mu2>
    <selfCollide>true</selfCollide>
  </gazebo>
  <gazebo reference="MCP_RING_v1_1">
    <material>Gazebo/Silver</material>
    <mu1>0.2</mu1>
    <mu2>0.2</mu2>
    <selfCollide>true</selfCollide>
  </gazebo>
  <gazebo reference="PIP_RING_v1_1">
    <material>Gazebo/Silver</material>
    <mu1>0.2</mu1>
    <mu2>0.2</mu2>
    <selfCollide>true</selfCollide>
  </gazebo>
  <gazebo reference="DIP_RING_v1_1">
    <material>Gazebo/Silver</material>
    <mu1>0.2</mu1>
    <mu2>0.2</mu2>
    <selfCollide>true</selfCollide>
  </gazebo>
  <gazebo reference="MCP_PINKY_v1_1">
    <material>Gazebo/Silver</material>
    <mu1>0.2</mu1>
    <mu2>0.2</mu2>
    <selfCollide>true</selfCollide>
  </gazebo>
  <gazebo reference="PIP_PINKY_v1_1">
    <material>Gazebo/Silver</material>
    <mu1>0.2</mu1>
    <mu2>0.2</mu2>
    <selfCollide>true</selfCollide>
  </gazebo>
  <gazebo reference="DIP_PINKY_v1_1">
    <material>Gazebo/Silver</material>
    <mu1>0.2</mu1>
    <mu2>0.2</mu2>
    <selfCollide>true</selfCollide>
  </gazebo>
  <gazebo reference="CMC_THUMB_v1_1">
    <material>Gazebo/Silver</material>
    <mu1>0.2</mu1>
    <mu2>0.2</mu2>
    <selfCollide>true</selfCollide>
  </gazebo>
  <gazebo reference="MCP_THUMB_v1_1">
    <material>Gazebo/Silver</material>
    <mu1>0.2</mu1>
    <mu2>0.2</mu2>
    <selfCollide>true</selfCollide>
  </gazebo>
  <gazebo reference="IP_THUMB_v1_1">
    <material>Gazebo/Silver</material>
    <mu1>0.2</mu1>
    <mu2>0.2</mu2>
    <selfCollide>true</selfCollide>
  </gazebo>
  <link name="base_link">
    <inertial>
      <origin rpy="0 0 0" xyz="-0.019740927704457817 1.3457673689547237e-14 3.8533067113950575e-17"/>
      <mass value="0.9441186699032876"/>
      <inertia ixx="0.001443" ixy="0.0" ixz="0.0" iyy="0.00109" iyz="0.0" izz="0.00109"/>
    </inertial>
    <visual>
      <origin rpy="0 0 0" xyz="0 0 0"/>
      <geometry>
        <mesh filename="stl/base_link.stl" scale="0.001 0.001 0.001"/>
      </geometry>
      <material name="silver"/>
    </visual>
    <collision>
      <origin rpy="0 0 0" xyz="0 0 0"/>
      <geometry>
        <mesh filename="stl/base_link.stl" scale="0.001 0.001 0.001"/>
      </geometry>
    </collision>
  </link>
  <link name="shoulder_link_1_v9_1">
    <inertial>
      <origin rpy="0 0 0" xyz="-0.05770403492587607 -0.008527336789003734 -4.370462209529847e-17"/>
      <mass value="1.461904936741723"/>
      <inertia ixx="0.00176" ixy="-2.5e-05" ixz="0.0" iyy="0.002844" iyz="-0.0" izz="0.002142"/>
    </inertial>
    <visual>
      <origin rpy="0 0 0" xyz="0.0505 -0.0 -0.0"/>
      <geometry>
        <mesh filename="stl/shoulder_link_1_v9_1.stl" scale="0.001 0.001 0.001"/>
      </geometry>
      <material name="silver"/>
    </visual>
    <collision>
      <origin rpy="0 0 0" xyz="0.0505 -0.0 -0.0"/>
      <geometry>
        <mesh filename="stl/shoulder_link_1_v9_1.stl" scale="0.001 0.001 0.001"/>
      </geometry>
    </collision>
  </link>
  <link name="shoulder_link_2_v4_1">
    <inertial>
      <origin rpy="0 0 0" xyz="-1.0824674490095276e-15 -0.02182197787303971 0.1307570313026753"/>
      <mass value="1.3282348020561616"/>
      <inertia ixx="0.009192" ixy="-0.0" ixz="0.0" iyy="0.008769" iyz="0.001996" izz="0.002511"/>
    </inertial>
    <visual>
      <origin rpy="0 0 0" xyz="0.1155 -0.0255 0.0"/>
      <geometry>
        <mesh filename="stl/shoulder_link_2_v4_1.stl" scale="0.001 0.001 0.001"/>
      </geometry>
      <material name="silver"/>
    </visual>
    <collision>
      <origin rpy="0 0 0" xyz="0.1155 -0.0255 0.0"/>
      <geometry>
        <mesh filename="stl/shoulder_link_2_v4_1.stl" scale="0.001 0.001 0.001"/>
      </geometry>
    </collision>
  </link>
  <link name="elbow_link_1_v6_1">
    <inertial>
      <origin rpy="0 0 0" xyz="-7.449883424870407e-05 -1.686498163344652e-14 0.08199752945418987"/>
      <mass value="1.309944313217933"/>
      <inertia ixx="0.003236" ixy="-0.0" ixz="2e-06" iyy="0.002776" iyz="0.0" izz="0.001275"/>
    </inertial>
    <visual>
      <origin rpy="0 0 0" xyz="0.1155 0.024 -0.2112"/>
      <geometry>
        <mesh filename="stl/elbow_link_1_v6_1.stl" scale="0.001 0.001 0.001"/>
      </geometry>
      <material name="silver"/>
    </visual>
    <collision>
      <origin rpy="0 0 0" xyz="0.1155 0.024 -0.2112"/>
      <geometry>
        <mesh filename="stl/elbow_link_1_v6_1.stl" scale="0.001 0.001 0.001"/>
      </geometry>
    </collision>
  </link>
  <link name="elbow_link_2_v7_1">
    <inertial>
      <origin rpy="0 0 0" xyz="0.03261486460573136 0.06783952555352682 -1.0236256287043943e-13"/>
      <mass value="1.3057586881176477"/>
      <inertia ixx="0.002958" ixy="-0.000913" ixz="0.0" iyy="0.002405" iyz="0.0" izz="0.003447"/>
    </inertial>
    <visual>
      <origin rpy="0 0 0" xyz="0.140875 0.024 -0.3167"/>
      <geometry>
        <mesh filename="stl/elbow_link_2_v7_1.stl" scale="0.001 0.001 0.001"/>
      </geometry>
      <material name="silver"/>
    </visual>
    <collision>
      <origin rpy="0 0 0" xyz="0.140875 0.024 -0.3167"/>
      <geometry>
        <mesh filename="stl/elbow_link_2_v7_1.stl" scale="0.001 0.001 0.001"/>
      </geometry>
    </collision>
  </link>
  <link name="forearm_v8_1">
    <inertial>
      <origin rpy="0 0 0" xyz="-1.249000902703301e-16 0.13257548053089302 -1.6653345369377348e-16"/>
      <mass value="1.6734453667565803"/>
      <inertia ixx="0.012845" ixy="0.0" ixz="-0.0" iyy="0.002559" iyz="0.0" izz="0.012861"/>
    </inertial>
    <visual>
      <origin rpy="0 0 0" xyz="0.091375 -0.0872 -0.3167"/>
      <geometry>
        <mesh filename="stl/forearm_v8_1.stl" scale="0.001 0.001 0.001"/>
      </geometry>
      <material name="silver"/>
    </visual>
    <collision>
      <origin rpy="0 0 0" xyz="0.091375 -0.0872 -0.3167"/>
      <geometry>
        <mesh filename="stl/forearm_v8_1.stl" scale="0.001 0.001 0.001"/>
      </geometry>
    </collision>
  </link>
  <link name="PALM_GAVIN_1DoF_Hinge_v2_1">
    <inertial>
      <origin rpy="0 0 0" xyz="-0.02233077416183611 0.05564826970859299 -0.0005939986128069008"/>
      <mass value="2.120157220826746"/>
      <inertia ixx="0.001678" ixy="-0.000146" ixz="-1.2e-05" iyy="0.001983" iyz="8e-06" izz="0.003293"/>
    </inertial>
    <visual>
      <origin rpy="0 0 0" xyz="0.066375 -0.3582 -0.3167"/>
      <geometry>
        <mesh filename="stl/PALM_GAVIN_1DoF_Hinge_v2_1.stl" scale="0.001 0.001 0.001"/>
      </geometry>
      <material name="silver"/>
    </visual>
    <collision>
      <origin rpy="0 0 0" xyz="0.066375 -0.3582 -0.3167"/>
      <geometry>
        <mesh filename="stl/PALM_GAVIN_1DoF_Hinge_v2_1.stl" scale="0.001 0.001 0.001"/>
      </geometry>
    </collision>
  </link>
  <link name="MCP_INDEX_v1_1">
    <inertial>
      <origin rpy="0 0 0" xyz="-0.005500073865622103 0.01750001303136789 -9.906511555524133e-09"/>
      <mass value="0.06647168215903997"/>
      <inertia ixx="1.1e-05" ixy="-0.0" ixz="-0.0" iyy="4e-06" iyz="-0.0" izz="1.2e-05"/>
    </inertial>
    <visual>
      <origin rpy="0 0 0" xyz="0.047125 -0.4652 -0.3172"/>
      <geometry>
        <mesh filename="stl/MCP_INDEX_v1_1.stl" scale="0.001 0.001 0.001"/>
      </geometry>
      <material name="silver"/>
    </visual>
    <collision>
      <origin rpy="0 0 0" xyz="0.047125 -0.4652 -0.3172"/>
      <geometry>
        <mesh filename="stl/MCP_INDEX_v1_1.stl" scale="0.001 0.001 0.001"/>
      </geometry>
    </collision>
  </link>
  <link name="PIP_INDEX_v1_1">
    <inertial>
      <origin rpy="0 0 0" xyz="-0.004750000108759811 0.00046534152117705396 0.01500290577629576"/>
      <mass value="0.07147211540799558"/>
      <inertia ixx="1.4e-05" ixy="0.0" ixz="-0.0" iyy="1.2e-05" iyz="-0.0" izz="3e-06"/>
    </inertial>
    <visual>
      <origin rpy="0 0 0" xyz="0.047125 -0.500608 -0.3172"/>
      <geometry>
        <mesh filename="stl/PIP_INDEX_v1_1.stl" scale="0.001 0.001 0.001"/>
      </geometry>
      <material name="silver"/>
    </visual>
    <collision>
      <origin rpy="0 0 0" xyz="0.047125 -0.500608 -0.3172"/>
      <geometry>
        <mesh filename="stl/PIP_INDEX_v1_1.stl" scale="0.001 0.001 0.001"/>
      </geometry>
    </collision>
  </link>
  <link name="DIP_INDEX_v1_1">
    <inertial>
      <origin rpy="0 0 0" xyz="0.005500032329403284 0.0015673194953499392 0.010811235762022087"/>
      <mass value="0.04298333664796617"/>
      <inertia ixx="4e-06" ixy="0.0" ixz="0.0" iyy="4e-06" iyz="-0.0" izz="2e-06"/>
    </inertial>
    <visual>
      <origin rpy="0 0 0" xyz="0.056625 -0.500608 -0.3472"/>
      <geometry>
        <mesh filename="stl/DIP_INDEX_v1_1.stl" scale="0.001 0.001 0.001"/>
      </geometry>
      <material name="silver"/>
    </visual>
    <collision>
      <origin rpy="0 0 0" xyz="0.056625 -0.500608 -0.3472"/>
      <geometry>
        <mesh filename="stl/DIP_INDEX_v1_1.stl" scale="0.001 0.001 0.001"/>
      </geometry>
    </collision>
  </link>
  <link name="MCP_MIDDLE_v1_1">
    <inertial>
      <origin rpy="0 0 0" xyz="-0.005500073865621832 0.0175000130313685 -9.906511222457226e-09"/>
      <mass value="0.06647168215903997"/>
      <inertia ixx="1.1e-05" ixy="-0.0" ixz="-0.0" iyy="4e-06" iyz="-0.0" izz="1.2e-05"/>
    </inertial>
    <visual>
      <origin rpy="0 0 0" xyz="0.073125 -0.4752 -0.3172"/>
      <geometry>
        <mesh filename="stl/MCP_MIDDLE_v1_1.stl" scale="0.001 0.001 0.001"/>
      </geometry>
      <material name="silver"/>
    </visual>
    <collision>
      <origin rpy="0 0 0" xyz="0.073125 -0.4752 -0.3172"/>
      <geometry>
        <mesh filename="stl/MCP_MIDDLE_v1_1.stl" scale="0.001 0.001 0.001"/>
      </geometry>
    </collision>
  </link>
  <link name="PIP_MIDDLE_v1_1">
    <inertial>
      <origin rpy="0 0 0" xyz="-0.004750000108759589 0.00046520863089893894 0.01500290577629615"/>
      <mass value="0.07147211540799558"/>
      <inertia ixx="1.4e-05" ixy="0.0" ixz="-0.0" iyy="1.2e-05" iyz="-0.0" izz="3e-06"/>
    </inertial>
    <visual>
      <origin rpy="0 0 0" xyz="0.073125 -0.5102 -0.3172"/>
      <geometry>
        <mesh filename="stl/PIP_MIDDLE_v1_1.stl" scale="0.001 0.001 0.001"/>
      </geometry>
      <material name="silver"/>
    </visual>
    <collision>
      <origin rpy="0 0 0" xyz="0.073125 -0.5102 -0.3172"/>
      <geometry>
        <mesh filename="stl/PIP_MIDDLE_v1_1.stl" scale="0.001 0.001 0.001"/>
      </geometry>
    </collision>
  </link>
  <link name="DIP_MIDDLE_v1_1">
    <inertial>
      <origin rpy="0 0 0" xyz="0.005500032329403465 -0.010811235761943538 0.0015671866051498728"/>
      <mass value="0.04298333664796617"/>
      <inertia ixx="4e-06" ixy="-0.0" ixz="0.0" iyy="2e-06" iyz="0.0" izz="4e-06"/>
    </inertial>
    <visual>
      <origin rpy="0 0 0" xyz="0.082625 -0.5102 -0.3472"/>
      <geometry>
        <mesh filename="stl/DIP_MIDDLE_v1_1.stl" scale="0.001 0.001 0.001"/>
      </geometry>
      <material name="silver"/>
    </visual>
    <collision>
      <origin rpy="0 0 0" xyz="0.082625 -0.5102 -0.3472"/>
      <geometry>
        <mesh filename="stl/DIP_MIDDLE_v1_1.stl" scale="0.001 0.001 0.001"/>
      </geometry>
    </collision>
  </link>
  <link name="MCP_RING_v1_1">
    <inertial>
      <origin rpy="0 0 0" xyz="0.0054999261343779 -9.90658988175852e-09 0.017499986968709524"/>
      <mass value="0.06647168215903997"/>
      <inertia ixx="1.1e-05" ixy="-0.0" ixz="0.0" iyy="1.2e-05" iyz="0.0" izz="4e-06"/>
    </inertial>
    <visual>
      <origin rpy="0 0 0" xyz="0.108625 -0.4652 -0.3172"/>
      <geometry>
        <mesh filename="stl/MCP_RING_v1_1.stl" scale="0.001 0.001 0.001"/>
      </geometry>
      <material name="silver"/>
    </visual>
    <collision>
      <origin rpy="0 0 0" xyz="0.108625 -0.4652 -0.3172"/>
      <geometry>
        <mesh filename="stl/MCP_RING_v1_1.stl" scale="0.001 0.001 0.001"/>
      </geometry>
    </collision>
  </link>
  <link name="PIP_RING_v1_1">
    <inertial>
      <origin rpy="0 0 0" xyz="-0.004750000108759797 0.0004652086308983283 0.015002905776295317"/>
      <mass value="0.07147211540799558"/>
      <inertia ixx="1.4e-05" ixy="0.0" ixz="-0.0" iyy="1.2e-05" iyz="-0.0" izz="3e-06"/>
    </inertial>
    <visual>
      <origin rpy="0 0 0" xyz="0.097625 -0.4652 -0.3522"/>
      <geometry>
        <mesh filename="stl/PIP_RING_v1_1.stl" scale="0.001 0.001 0.001"/>
      </geometry>
      <material name="silver"/>
    </visual>
    <collision>
      <origin rpy="0 0 0" xyz="0.097625 -0.4652 -0.3522"/>
      <geometry>
        <mesh filename="stl/PIP_RING_v1_1.stl" scale="0.001 0.001 0.001"/>
      </geometry>
    </collision>
  </link>
  <link name="DIP_RING_v1_1">
    <inertial>
      <origin rpy="0 0 0" xyz="-0.005499967670596823 0.0015671866050709915 0.010811235762021754"/>
      <mass value="0.04298333664796617"/>
      <inertia ixx="4e-06" ixy="0.0" ixz="0.0" iyy="4e-06" iyz="-0.0" izz="2e-06"/>
    </inertial>
    <visual>
      <origin rpy="0 0 0" xyz="0.097625 -0.4652 -0.3822"/>
      <geometry>
        <mesh filename="stl/DIP_RING_v1_1.stl" scale="0.001 0.001 0.001"/>
      </geometry>
      <material name="silver"/>
    </visual>
    <collision>
      <origin rpy="0 0 0" xyz="0.097625 -0.4652 -0.3822"/>
      <geometry>
        <mesh filename="stl/DIP_RING_v1_1.stl" scale="0.001 0.001 0.001"/>
      </geometry>
    </collision>
  </link>
  <link name="MCP_PINKY_v1_1">
    <inertial>
      <origin rpy="0 0 0" xyz="-0.005500073865622179 -9.906589937269672e-09 0.017499986968709635"/>
      <mass value="0.06647168215903997"/>
      <inertia ixx="1.1e-05" ixy="-0.0" ixz="0.0" iyy="1.2e-05" iyz="0.0" izz="4e-06"/>
    </inertial>
    <visual>
      <origin rpy="0 0 0" xyz="0.125125 -0.4502 -0.3172"/>
      <geometry>
        <mesh filename="stl/MCP_PINKY_v1_1.stl" scale="0.001 0.001 0.001"/>
      </geometry>
      <material name="silver"/>
    </visual>
    <collision>
      <origin rpy="0 0 0" xyz="0.125125 -0.4502 -0.3172"/>
      <geometry>
        <mesh filename="stl/MCP_PINKY_v1_1.stl" scale="0.001 0.001 0.001"/>
      </geometry>
    </collision>
  </link>
  <link name="PIP_PINKY_v1_1">
    <inertial>
      <origin rpy="0 0 0" xyz="-0.004750000108759894 0.00046520863089805076 0.015002905776295705"/>
      <mass value="0.07147211540799558"/>
      <inertia ixx="1.4e-05" ixy="0.0" ixz="-0.0" iyy="1.2e-05" iyz="-0.0" izz="3e-06"/>
    </inertial>
    <visual>
      <origin rpy="0 0 0" xyz="0.125125 -0.4502 -0.3522"/>
      <geometry>
        <mesh filename="stl/PIP_PINKY_v1_1.stl" scale="0.001 0.001 0.001"/>
      </geometry>
      <material name="silver"/>
    </visual>
    <collision>
      <origin rpy="0 0 0" xyz="0.125125 -0.4502 -0.3522"/>
      <geometry>
        <mesh filename="stl/PIP_PINKY_v1_1.stl" scale="0.001 0.001 0.001"/>
      </geometry>
    </collision>
  </link>
  <link name="DIP_PINKY_v1_1">
    <inertial>
      <origin rpy="0 0 0" xyz="0.005500032329403132 -0.01081123576194426 0.0015671866051495398"/>
      <mass value="0.04298333664796617"/>
      <inertia ixx="4e-06" ixy="-0.0" ixz="0.0" iyy="2e-06" iyz="0.0" izz="4e-06"/>
    </inertial>
    <visual>
      <origin rpy="0 0 0" xyz="0.134625 -0.4502 -0.3822"/>
      <geometry>
        <mesh filename="stl/DIP_PINKY_v1_1.stl" scale="0.001 0.001 0.001"/>
      </geometry>
      <material name="silver"/>
    </visual>
    <collision>
      <origin rpy="0 0 0" xyz="0.134625 -0.4502 -0.3822"/>
      <geometry>
        <mesh filename="stl/DIP_PINKY_v1_1.stl" scale="0.001 0.001 0.001"/>
      </geometry>
    </collision>
  </link>
  <link name="CMC_THUMB_v1_1">
    <inertial>
      <origin rpy="0 0 0" xyz="0.008171816525932303 -0.014667673892031718 -0.00026820961939072463"/>
      <mass value="0.1776914594904236"/>
      <inertia ixx="2.5e-05" ixy="-5e-06" ixz="-1e-06" iyy="2.6e-05" iyz="0.0" izz="3.4e-05"/>
    </inertial>
    <visual>
      <origin rpy="0 0 0" xyz="0.046875 -0.4132 -0.3472"/>
      <geometry>
        <mesh filename="stl/CMC_THUMB_v1_1.stl" scale="0.001 0.001 0.001"/>
      </geometry>
      <material name="silver"/>
    </visual>
    <collision>
      <origin rpy="0 0 0" xyz="0.046875 -0.4132 -0.3472"/>
      <geometry>
        <mesh filename="stl/CMC_THUMB_v1_1.stl" scale="0.001 0.001 0.001"/>
      </geometry>
    </collision>
  </link>
  <link name="MCP_THUMB_v1_1">
    <inertial>
      <origin rpy="0 0 0" xyz="-0.006064265496711459 0.004028448988576683 0.013953206162800103"/>
      <mass value="0.07147211540799558"/>
      <inertia ixx="9e-06" ixy="2e-06" ixz="4e-06" iyy="1.1e-05" iyz="-3e-06" izz="8e-06"/>
    </inertial>
    <visual>
      <origin rpy="0 0 0" xyz="0.024611 -0.415171 -0.343493"/>
      <geometry>
        <mesh filename="stl/MCP_THUMB_v1_1.stl" scale="0.001 0.001 0.001"/>
      </geometry>
      <material name="silver"/>
    </visual>
    <collision>
      <origin rpy="0 0 0" xyz="0.024611 -0.415171 -0.343493"/>
      <geometry>
        <mesh filename="stl/MCP_THUMB_v1_1.stl" scale="0.001 0.001 0.001"/>
      </geometry>
    </collision>
  </link>
  <link name="IP_THUMB_v1_1">
    <inertial>
      <origin rpy="0 0 0" xyz="-0.0025155403138474933 0.002948794560108714 0.011600043359116574"/>
      <mass value="0.04298333664796617"/>
      <inertia ixx="4e-06" ixy="1e-06" ixz="1e-06" iyy="4e-06" iyz="-1e-06" izz="3e-06"/>
    </inertial>
    <visual>
      <origin rpy="0 0 0" xyz="0.042442 -0.426802 -0.36463"/>
      <geometry>
        <mesh filename="stl/IP_THUMB_v1_1.stl" scale="0.001 0.001 0.001"/>
      </geometry>
      <material name="silver"/>
    </visual>
    <collision>
      <origin rpy="0 0 0" xyz="0.042442 -0.426802 -0.36463"/>
      <geometry>
        <mesh filename="stl/IP_THUMB_v1_1.stl" scale="0.001 0.001 0.001"/>
      </geometry>
    </collision>
  </link>
  <joint name="shoulder_flexion_extension" type="continuous">
    <origin rpy="0 0 0" xyz="-0.0505 0.0 0.0"/>
    <parent link="base_link"/>
    <child link="shoulder_link_1_v9_1"/>
    <axis xyz="1.0 0.0 0.0"/>
  </joint>
  <joint name="shoulder_abduction_adduction" type="revolute">
    <origin rpy="0 0 0" xyz="-0.065 0.0255 -0.0"/>
    <parent link="shoulder_link_1_v9_1"/>
    <child link="shoulder_link_2_v4_1"/>
    <axis xyz="0.0 -1.0 0.0"/>
    <limit effort="100" lower="-0.349066" upper="3.490659" velocity="100"/>
  </joint>
  <joint name="shoulder_rotation" type="continuous">
    <origin rpy="0 0 0" xyz="0.0 -0.0495 0.2112"/>
    <parent link="shoulder_link_2_v4_1"/>
    <child link="elbow_link_1_v6_1"/>
    <axis xyz="0.0 0.0 -1.0"/>
  </joint>
  <joint name="elbow_flexion_extension" type="revolute">
    <origin rpy="0 0 0" xyz="-0.025375 0.0 0.1055"/>
    <parent link="elbow_link_1_v6_1"/>
    <child link="elbow_link_2_v7_1"/>
    <axis xyz="1.0 -0.0 -0.0"/>
    <limit effort="100" lower="-0.349066" upper="3.490659" velocity="100"/>
  </joint>
  <joint name="forearm_rotation" type="revolute">
    <origin rpy="0 0 0" xyz="0.0495 0.1112 0.0"/>
    <parent link="elbow_link_2_v7_1"/>
    <child link="forearm_v8_1"/>
    <axis xyz="-0.0 -1.0 0.0"/>
    <limit effort="100" lower="0.0" upper="3.14" velocity="100"/>
  </joint>
  <joint name="wrist_extension" type="revolute">
    <origin rpy="0 0 0" xyz="0.025 0.271 0.0"/>
    <parent link="forearm_v8_1"/>
    <child link="PALM_GAVIN_1DoF_Hinge_v2_1"/>
    <axis xyz="-1.0 0.0 0.0"/>
    <limit effort="100" lower="-0.959931" upper="0.959931" velocity="100"/>
  </joint>
  <joint name="mcp_index" type="revolute">
    <origin rpy="0 0 0" xyz="0.01925 0.107 0.0005"/>
    <parent link="PALM_GAVIN_1DoF_Hinge_v2_1"/>
    <child link="MCP_INDEX_v1_1"/>
    <axis xyz="-1.0 0.0 0.0"/>
    <limit effort="100" lower="-1.570796" upper="0.0" velocity="100"/>
  </joint>
  <joint name="pip_index" type="revolute">
    <origin rpy="0 0 0" xyz="0.0 0.035408 0.0"/>
    <parent link="MCP_INDEX_v1_1"/>
    <child link="PIP_INDEX_v1_1"/>
    <axis xyz="-1.0 0.0 0.0"/>
    <limit effort="100" lower="0.0" upper="1.570796" velocity="100"/>
  </joint>
  <joint name="dip_index" type="revolute">
    <origin rpy="0 0 0" xyz="-0.0095 0.0 0.03"/>
    <parent link="PIP_INDEX_v1_1"/>
    <child link="DIP_INDEX_v1_1"/>
    <axis xyz="-1.0 0.0 0.0"/>
    <limit effort="100" lower="-1.570796" upper="0.0" velocity="100"/>
  </joint>
  <joint name="mcp_middle" type="revolute">
    <origin rpy="0 0 0" xyz="-0.00675 0.117 0.0005"/>
    <parent link="PALM_GAVIN_1DoF_Hinge_v2_1"/>
    <child link="MCP_MIDDLE_v1_1"/>
    <axis xyz="-1.0 0.0 0.0"/>
    <limit effort="100" lower="-1.570796" upper="0.0" velocity="100"/>
  </joint>
  <joint name="pip_middle" type="revolute">
    <origin rpy="0 0 0" xyz="0.0 0.035 0.0"/>
    <parent link="MCP_MIDDLE_v1_1"/>
    <child link="PIP_MIDDLE_v1_1"/>
    <axis xyz="-1.0 -0.0 0.0"/>
    <limit effort="100" lower="0.0" upper="1.570796" velocity="100"/>
  </joint>
  <joint name="dip_middle" type="revolute">
    <origin rpy="0 0 0" xyz="-0.0095 0.0 0.03"/>
    <parent link="PIP_MIDDLE_v1_1"/>
    <child link="DIP_MIDDLE_v1_1"/>
    <axis xyz="-1.0 -0.0 0.0"/>
    <limit effort="100" lower="0.0" upper="1.570796" velocity="100"/>
  </joint>
  <joint name="mcp_ring" type="revolute">
    <origin rpy="0 0 0" xyz="-0.04225 0.107 0.0005"/>
    <parent link="PALM_GAVIN_1DoF_Hinge_v2_1"/>
    <child link="MCP_RING_v1_1"/>
    <axis xyz="-1.0 -0.0 -0.0"/>
    <limit effort="100" lower="0.0" upper="1.570796" velocity="100"/>
  </joint>
  <joint name="pip_ring" type="revolute">
    <origin rpy="0 0 0" xyz="0.011 0.0 0.035"/>
    <parent link="MCP_RING_v1_1"/>
    <child link="PIP_RING_v1_1"/>
    <axis xyz="-1.0 0.0 0.0"/>
    <limit effort="100" lower="-1.570796" upper="0.0" velocity="100"/>
  </joint>
  <joint name="dip_ring" type="revolute">
    <origin rpy="0 0 0" xyz="0.0 0.0 0.03"/>
    <parent link="PIP_RING_v1_1"/>
    <child link="DIP_RING_v1_1"/>
    <axis xyz="-1.0 0.0 0.0"/>
    <limit effort="100" lower="-1.570796" upper="0.0" velocity="100"/>
  </joint>
  <joint name="mcp_pinky" type="revolute">
    <origin rpy="0 0 0" xyz="-0.05875 0.092 0.0005"/>
    <parent link="PALM_GAVIN_1DoF_Hinge_v2_1"/>
    <child link="MCP_PINKY_v1_1"/>
    <axis xyz="-1.0 0.0 0.0"/>
    <limit effort="100" lower="0.0" upper="1.570796" velocity="100"/>
  </joint>
  <joint name="pip_pinky" type="revolute">
    <origin rpy="0 0 0" xyz="0.0 0.0 0.035"/>
    <parent link="MCP_PINKY_v1_1"/>
    <child link="PIP_PINKY_v1_1"/>
    <axis xyz="-1.0 0.0 0.0"/>
    <limit effort="100" lower="-1.570796" upper="0.0" velocity="100"/>
  </joint>
  <joint name="dip_pinky" type="revolute">
    <origin rpy="0 0 0" xyz="-0.0095 0.0 0.03"/>
    <parent link="PIP_PINKY_v1_1"/>
    <child link="DIP_PINKY_v1_1"/>
    <axis xyz="-1.0 0.0 0.0"/>
    <limit effort="100" lower="0.0" upper="1.570796" velocity="100"/>
  </joint>
  <joint name="cmc_thumb" type="revolute">
    <origin rpy="0 0 0" xyz="0.0195 0.055 0.0305"/>
    <parent link="PALM_GAVIN_1DoF_Hinge_v2_1"/>
    <child link="CMC_THUMB_v1_1"/>
    <axis xyz="-0.0 -1.0 -0.0"/>
    <limit effort="100" lower="-0.349066" upper="2.094395" velocity="100"/>
  </joint>
  <joint name="mcp_thumb" type="revolute">
    <origin rpy="0 0 0" xyz="0.022264 0.001971 -0.003707"/>
    <parent link="CMC_THUMB_v1_1"/>
    <child link="MCP_THUMB_v1_1"/>
    <axis xyz="-0.541675 0.454519 -0.707107"/>
    <limit effort="100" lower="0.785398" upper="2.530727" velocity="100"/>
  </joint>
  <joint name="ip_thumb" type="revolute">
    <origin rpy="0 0 0" xyz="-0.017831 0.011631 0.021137"/>
    <parent link="MCP_THUMB_v1_1"/>
    <child link="IP_THUMB_v1_1"/>
    <axis xyz="0.541675 -0.454519 0.707107"/>
    <limit effort="100" lower="0.0" upper="1.570796" velocity="100"/>
  </joint>
</robot>

  <!--
  Joint drive TL;DR (Isaac/URDF importer):
  1) Get joint inertia J about each joint axis (from importer equivalent inertia or reflected subtree inertia).
  2) Pick target natural frequency f in Hz and damping ratio zeta (zeta=1.0 is critical damping).
  3) Convert to angular frequency: w = 2*pi*f (rad/s).
  4) Compute:
       stiffness k = J * w^2
       damping  d = 2 * zeta * J * w
     Units: k [N*m/rad], d [N*m*s/rad]

  Worked example (elbow_flexion_extension):
  - Use J = 0.767901 kg*m^2
  - Choose f = 4.5 Hz, zeta = 1.0
  - w = 2*pi*4.5 = 28.274 rad/s
  - k = 0.767901 * (28.274)^2 = 613.889 N*m/rad
  - d = 2 * 1.0 * 0.767901 * 28.274 = 43.424 N*m*s/rad

  Same work for every remaining joint:
  - Replace J and f with that joint's values, keep zeta (start with 1.0), then evaluate k and d.
  - If oscillatory: increase d or reduce f.
  - If too soft/sluggish: increase f gradually.
  -->
