<?xml version="1.0" ?>
<!-- =================================================================================== -->
<!-- |    This document was autogenerated by xacro from src/arm_assembly_4_description/urdf/arm_assembly_4.xacro | -->
<!-- |    EDITING THIS FILE BY HAND IS NOT RECOMMENDED                                 | -->
<!-- =================================================================================== -->
<robot name="arm_assembly_4">
  <material name="silver">
    <color rgba="0.700 0.700 0.700 1.000"/>
  </material>
  <transmission name="Revolute 1_tran">
    <type>transmission_interface/SimpleTransmission</type>
    <joint name="Revolute 1">
      <hardwareInterface>hardware_interface/EffortJointInterface</hardwareInterface>
    </joint>
    <actuator name="Revolute 1_actr">
      <hardwareInterface>hardware_interface/EffortJointInterface</hardwareInterface>
      <mechanicalReduction>1</mechanicalReduction>
    </actuator>
  </transmission>
  <transmission name="Revolute 2_tran">
    <type>transmission_interface/SimpleTransmission</type>
    <joint name="Revolute 2">
      <hardwareInterface>hardware_interface/EffortJointInterface</hardwareInterface>
    </joint>
    <actuator name="Revolute 2_actr">
      <hardwareInterface>hardware_interface/EffortJointInterface</hardwareInterface>
      <mechanicalReduction>1</mechanicalReduction>
    </actuator>
  </transmission>
  <transmission name="Revolute 3_tran">
    <type>transmission_interface/SimpleTransmission</type>
    <joint name="Revolute 3">
      <hardwareInterface>hardware_interface/EffortJointInterface</hardwareInterface>
    </joint>
    <actuator name="Revolute 3_actr">
      <hardwareInterface>hardware_interface/EffortJointInterface</hardwareInterface>
      <mechanicalReduction>1</mechanicalReduction>
    </actuator>
  </transmission>
  <transmission name="Revolute 4_tran">
    <type>transmission_interface/SimpleTransmission</type>
    <joint name="Revolute 4">
      <hardwareInterface>hardware_interface/EffortJointInterface</hardwareInterface>
    </joint>
    <actuator name="Revolute 4_actr">
      <hardwareInterface>hardware_interface/EffortJointInterface</hardwareInterface>
      <mechanicalReduction>1</mechanicalReduction>
    </actuator>
  </transmission>
  <transmission name="Revolute 5_tran">
    <type>transmission_interface/SimpleTransmission</type>
    <joint name="Revolute 5">
      <hardwareInterface>hardware_interface/EffortJointInterface</hardwareInterface>
    </joint>
    <actuator name="Revolute 5_actr">
      <hardwareInterface>hardware_interface/EffortJointInterface</hardwareInterface>
      <mechanicalReduction>1</mechanicalReduction>
    </actuator>
  </transmission>
  <transmission name="wrist_extension_tran">
    <type>transmission_interface/SimpleTransmission</type>
    <joint name="wrist_extension">
      <hardwareInterface>hardware_interface/EffortJointInterface</hardwareInterface>
    </joint>
    <actuator name="wrist_extension_actr">
      <hardwareInterface>hardware_interface/EffortJointInterface</hardwareInterface>
      <mechanicalReduction>1</mechanicalReduction>
    </actuator>
  </transmission>
  <transmission name="mcp_index_tran">
    <type>transmission_interface/SimpleTransmission</type>
    <joint name="mcp_index">
      <hardwareInterface>hardware_interface/EffortJointInterface</hardwareInterface>
    </joint>
    <actuator name="mcp_index_actr">
      <hardwareInterface>hardware_interface/EffortJointInterface</hardwareInterface>
      <mechanicalReduction>1</mechanicalReduction>
    </actuator>
  </transmission>
  <transmission name="Revolute 12_tran">
    <type>transmission_interface/SimpleTransmission</type>
    <joint name="Revolute 12">
      <hardwareInterface>hardware_interface/EffortJointInterface</hardwareInterface>
    </joint>
    <actuator name="Revolute 12_actr">
      <hardwareInterface>hardware_interface/EffortJointInterface</hardwareInterface>
      <mechanicalReduction>1</mechanicalReduction>
    </actuator>
  </transmission>
  <transmission name="Revolute 13_tran">
    <type>transmission_interface/SimpleTransmission</type>
    <joint name="Revolute 13">
      <hardwareInterface>hardware_interface/EffortJointInterface</hardwareInterface>
    </joint>
    <actuator name="Revolute 13_actr">
      <hardwareInterface>hardware_interface/EffortJointInterface</hardwareInterface>
      <mechanicalReduction>1</mechanicalReduction>
    </actuator>
  </transmission>
  <transmission name="Revolute 14_tran">
    <type>transmission_interface/SimpleTransmission</type>
    <joint name="Revolute 14">
      <hardwareInterface>hardware_interface/EffortJointInterface</hardwareInterface>
    </joint>
    <actuator name="Revolute 14_actr">
      <hardwareInterface>hardware_interface/EffortJointInterface</hardwareInterface>
      <mechanicalReduction>1</mechanicalReduction>
    </actuator>
  </transmission>
  <transmission name="Revolute 15_tran">
    <type>transmission_interface/SimpleTransmission</type>
    <joint name="Revolute 15">
      <hardwareInterface>hardware_interface/EffortJointInterface</hardwareInterface>
    </joint>
    <actuator name="Revolute 15_actr">
      <hardwareInterface>hardware_interface/EffortJointInterface</hardwareInterface>
      <mechanicalReduction>1</mechanicalReduction>
    </actuator>
  </transmission>
  <transmission name="Revolute 16_tran">
    <type>transmission_interface/SimpleTransmission</type>
    <joint name="Revolute 16">
      <hardwareInterface>hardware_interface/EffortJointInterface</hardwareInterface>
    </joint>
    <actuator name="Revolute 16_actr">
      <hardwareInterface>hardware_interface/EffortJointInterface</hardwareInterface>
      <mechanicalReduction>1</mechanicalReduction>
    </actuator>
  </transmission>
  <transmission name="Revolute 17_tran">
    <type>transmission_interface/SimpleTransmission</type>
    <joint name="Revolute 17">
      <hardwareInterface>hardware_interface/EffortJointInterface</hardwareInterface>
    </joint>
    <actuator name="Revolute 17_actr">
      <hardwareInterface>hardware_interface/EffortJointInterface</hardwareInterface>
      <mechanicalReduction>1</mechanicalReduction>
    </actuator>
  </transmission>
  <transmission name="Revolute 18_tran">
    <type>transmission_interface/SimpleTransmission</type>
    <joint name="Revolute 18">
      <hardwareInterface>hardware_interface/EffortJointInterface</hardwareInterface>
    </joint>
    <actuator name="Revolute 18_actr">
      <hardwareInterface>hardware_interface/EffortJointInterface</hardwareInterface>
      <mechanicalReduction>1</mechanicalReduction>
    </actuator>
  </transmission>
  <transmission name="Revolute 19_tran">
    <type>transmission_interface/SimpleTransmission</type>
    <joint name="Revolute 19">
      <hardwareInterface>hardware_interface/EffortJointInterface</hardwareInterface>
    </joint>
    <actuator name="Revolute 19_actr">
      <hardwareInterface>hardware_interface/EffortJointInterface</hardwareInterface>
      <mechanicalReduction>1</mechanicalReduction>
    </actuator>
  </transmission>
  <transmission name="mcp_pinky_tran">
    <type>transmission_interface/SimpleTransmission</type>
    <joint name="mcp_pinky">
      <hardwareInterface>hardware_interface/EffortJointInterface</hardwareInterface>
    </joint>
    <actuator name="mcp_pinky_actr">
      <hardwareInterface>hardware_interface/EffortJointInterface</hardwareInterface>
      <mechanicalReduction>1</mechanicalReduction>
    </actuator>
  </transmission>
  <transmission name="pip_pinky_tran">
    <type>transmission_interface/SimpleTransmission</type>
    <joint name="pip_pinky">
      <hardwareInterface>hardware_interface/EffortJointInterface</hardwareInterface>
    </joint>
    <actuator name="pip_pinky_actr">
      <hardwareInterface>hardware_interface/EffortJointInterface</hardwareInterface>
      <mechanicalReduction>1</mechanicalReduction>
    </actuator>
  </transmission>
  <transmission name="dip_pinky_tran">
    <type>transmission_interface/SimpleTransmission</type>
    <joint name="dip_pinky">
      <hardwareInterface>hardware_interface/EffortJointInterface</hardwareInterface>
    </joint>
    <actuator name="dip_pinky_actr">
      <hardwareInterface>hardware_interface/EffortJointInterface</hardwareInterface>
      <mechanicalReduction>1</mechanicalReduction>
    </actuator>
  </transmission>
  <transmission name="Revolute 23_tran">
    <type>transmission_interface/SimpleTransmission</type>
    <joint name="Revolute 23">
      <hardwareInterface>hardware_interface/EffortJointInterface</hardwareInterface>
    </joint>
    <actuator name="Revolute 23_actr">
      <hardwareInterface>hardware_interface/EffortJointInterface</hardwareInterface>
      <mechanicalReduction>1</mechanicalReduction>
    </actuator>
  </transmission>
  <transmission name="Revolute 24_tran">
    <type>transmission_interface/SimpleTransmission</type>
    <joint name="Revolute 24">
      <hardwareInterface>hardware_interface/EffortJointInterface</hardwareInterface>
    </joint>
    <actuator name="Revolute 24_actr">
      <hardwareInterface>hardware_interface/EffortJointInterface</hardwareInterface>
      <mechanicalReduction>1</mechanicalReduction>
    </actuator>
  </transmission>
  <transmission name="Revolute 25_tran">
    <type>transmission_interface/SimpleTransmission</type>
    <joint name="Revolute 25">
      <hardwareInterface>hardware_interface/EffortJointInterface</hardwareInterface>
    </joint>
    <actuator name="Revolute 25_actr">
      <hardwareInterface>hardware_interface/EffortJointInterface</hardwareInterface>
      <mechanicalReduction>1</mechanicalReduction>
    </actuator>
  </transmission>
  <gazebo>
    <plugin filename="libgazebo_ros_control.so" name="control"/>
  </gazebo>
  <gazebo reference="base_link">
    <material>Gazebo/Silver</material>
    <mu1>0.2</mu1>
    <mu2>0.2</mu2>
    <selfCollide>true</selfCollide>
    <gravity>true</gravity>
  </gazebo>
  <gazebo reference="shoulder_link_1_v9_1">
    <material>Gazebo/Silver</material>
    <mu1>0.2</mu1>
    <mu2>0.2</mu2>
    <selfCollide>true</selfCollide>
  </gazebo>
  <gazebo reference="shoulder_link_2_v4_1">
    <material>Gazebo/Silver</material>
    <mu1>0.2</mu1>
    <mu2>0.2</mu2>
    <selfCollide>true</selfCollide>
  </gazebo>
  <gazebo reference="elbow_link_1_v6_1">
    <material>Gazebo/Silver</material>
    <mu1>0.2</mu1>
    <mu2>0.2</mu2>
    <selfCollide>true</selfCollide>
  </gazebo>
  <gazebo reference="elbow_link_2_v7_1">
    <material>Gazebo/Silver</material>
    <mu1>0.2</mu1>
    <mu2>0.2</mu2>
    <selfCollide>true</selfCollide>
  </gazebo>
  <gazebo reference="forearm_v8_1">
    <material>Gazebo/Silver</material>
    <mu1>0.2</mu1>
    <mu2>0.2</mu2>
    <selfCollide>true</selfCollide>
  </gazebo>
  <gazebo reference="PALM_GAVIN_1DoF_Hinge_v2_1">
    <material>Gazebo/Silver</material>
    <mu1>0.2</mu1>
    <mu2>0.2</mu2>
    <selfCollide>true</selfCollide>
  </gazebo>
  <gazebo reference="MCP_INDEX_v1_1">
    <material>Gazebo/Silver</material>
    <mu1>0.2</mu1>
    <mu2>0.2</mu2>
    <selfCollide>true</selfCollide>
  </gazebo>
  <gazebo reference="PIP_INDEX_v1_1">
    <material>Gazebo/Silver</material>
    <mu1>0.2</mu1>
    <mu2>0.2</mu2>
    <selfCollide>true</selfCollide>
  </gazebo>
  <gazebo reference="DIP_INDEX_v1_1">
    <material>Gazebo/Silver</material>
    <mu1>0.2</mu1>
    <mu2>0.2</mu2>
    <selfCollide>true</selfCollide>
  </gazebo>
  <gazebo reference="MCP_MIDDLE_v1_1">
    <material>Gazebo/Silver</material>
    <mu1>0.2</mu1>
    <mu2>0.2</mu2>
    <selfCollide>true</selfCollide>
  </gazebo>
  <gazebo reference="PIP_MIDDLE_v1_1">
    <material>Gazebo/Silver</material>
    <mu1>0.2</mu1>
    <mu2>0.2</mu2>
    <selfCollide>true</selfCollide>
  </gazebo>
  <gazebo reference="DIP_MIDDLE_v1_1">
    <material>Gazebo/Silver</material>
    <mu1>0.2</mu1>
    <mu2>0.2</mu2>
    <selfCollide>true</selfCollide>
  </gazebo>
  <gazebo reference="MCP_RING_v1_1">
    <material>Gazebo/Silver</material>
    <mu1>0.2</mu1>
    <mu2>0.2</mu2>
    <selfCollide>true</selfCollide>
  </gazebo>
  <gazebo reference="PIP_RING_v1_1">
    <material>Gazebo/Silver</material>
    <mu1>0.2</mu1>
    <mu2>0.2</mu2>
    <selfCollide>true</selfCollide>
  </gazebo>
  <gazebo reference="DIP_RING_v1_1">
    <material>Gazebo/Silver</material>
    <mu1>0.2</mu1>
    <mu2>0.2</mu2>
    <selfCollide>true</selfCollide>
  </gazebo>
  <gazebo reference="MCP_PINKY_v1_1">
    <material>Gazebo/Silver</material>
    <mu1>0.2</mu1>
    <mu2>0.2</mu2>
    <selfCollide>true</selfCollide>
  </gazebo>
  <gazebo reference="PIP_PINKY_v1_1">
    <material>Gazebo/Silver</material>
    <mu1>0.2</mu1>
    <mu2>0.2</mu2>
    <selfCollide>true</selfCollide>
  </gazebo>
  <gazebo reference="DIP_PINKY_v1_1">
    <material>Gazebo/Silver</material>
    <mu1>0.2</mu1>
    <mu2>0.2</mu2>
    <selfCollide>true</selfCollide>
  </gazebo>
  <gazebo reference="CMC_THUMB_v1_1">
    <material>Gazebo/Silver</material>
    <mu1>0.2</mu1>
    <mu2>0.2</mu2>
    <selfCollide>true</selfCollide>
  </gazebo>
  <gazebo reference="MCP_THUMB_v1_1">
    <material>Gazebo/Silver</material>
    <mu1>0.2</mu1>
    <mu2>0.2</mu2>
    <selfCollide>true</selfCollide>
  </gazebo>
  <gazebo reference="IP_THUMB_v1_1">
    <material>Gazebo/Silver</material>
    <mu1>0.2</mu1>
    <mu2>0.2</mu2>
    <selfCollide>true</selfCollide>
  </gazebo>
  <link name="base_link">
    <inertial>
      <origin rpy="0 0 0" xyz="-0.019740927704457817 1.3457673689547237e-14 3.8533067113950575e-17"/>
      <mass value="0.9441186699032876"/>
      <inertia ixx="0.001443" ixy="0.0" ixz="0.0" iyy="0.00109" iyz="0.0" izz="0.00109"/>
    </inertial>
    <visual>
      <origin rpy="0 0 0" xyz="0 0 0"/>
      <geometry>
        <mesh filename="package://arm_assembly_4_description/meshes/base_link.stl" scale="0.001 0.001 0.001"/>
      </geometry>
      <material name="silver"/>
    </visual>
    <collision>
      <origin rpy="0 0 0" xyz="0 0 0"/>
      <geometry>
        <mesh filename="package://arm_assembly_4_description/meshes/base_link.stl" scale="0.001 0.001 0.001"/>
      </geometry>
    </collision>
  </link>
  <link name="shoulder_link_1_v9_1">
    <inertial>
      <origin rpy="0 0 0" xyz="-0.057704034925876044 -0.008527336789003727 -1.555324629725915e-19"/>
      <mass value="1.4619049367417225"/>
      <inertia ixx="0.00176" ixy="-2.5e-05" ixz="0.0" iyy="0.002844" iyz="-0.0" izz="0.002142"/>
    </inertial>
    <visual>
      <origin rpy="0 0 0" xyz="0.0505 -0.0 -0.0"/>
      <geometry>
        <mesh filename="package://arm_assembly_4_description/meshes/shoulder_link_1_v9_1.stl" scale="0.001 0.001 0.001"/>
      </geometry>
      <material name="silver"/>
    </visual>
    <collision>
      <origin rpy="0 0 0" xyz="0.0505 -0.0 -0.0"/>
      <geometry>
        <mesh filename="package://arm_assembly_4_description/meshes/shoulder_link_1_v9_1.stl" scale="0.001 0.001 0.001"/>
      </geometry>
    </collision>
  </link>
  <link name="shoulder_link_2_v4_1">
    <inertial>
      <origin rpy="0 0 0" xyz="-1.0824674490095276e-15 -0.021821977873039675 0.1307570313026753"/>
      <mass value="1.3282348020561616"/>
      <inertia ixx="0.009192" ixy="-0.0" ixz="0.0" iyy="0.008769" iyz="0.001996" izz="0.002511"/>
    </inertial>
    <visual>
      <origin rpy="0 0 0" xyz="0.1155 -0.0255 0.0"/>
      <geometry>
        <mesh filename="package://arm_assembly_4_description/meshes/shoulder_link_2_v4_1.stl" scale="0.001 0.001 0.001"/>
      </geometry>
      <material name="silver"/>
    </visual>
    <collision>
      <origin rpy="0 0 0" xyz="0.1155 -0.0255 0.0"/>
      <geometry>
        <mesh filename="package://arm_assembly_4_description/meshes/shoulder_link_2_v4_1.stl" scale="0.001 0.001 0.001"/>
      </geometry>
    </collision>
  </link>
  <link name="elbow_link_1_v6_1">
    <inertial>
      <origin rpy="0 0 0" xyz="-7.449883424870407e-05 -1.6830287163926982e-14 0.08199752945418987"/>
      <mass value="1.309944313217933"/>
      <inertia ixx="0.003236" ixy="-0.0" ixz="2e-06" iyy="0.002776" iyz="0.0" izz="0.001275"/>
    </inertial>
    <visual>
      <origin rpy="0 0 0" xyz="0.1155 0.024 -0.2112"/>
      <geometry>
        <mesh filename="package://arm_assembly_4_description/meshes/elbow_link_1_v6_1.stl" scale="0.001 0.001 0.001"/>
      </geometry>
      <material name="silver"/>
    </visual>
    <collision>
      <origin rpy="0 0 0" xyz="0.1155 0.024 -0.2112"/>
      <geometry>
        <mesh filename="package://arm_assembly_4_description/meshes/elbow_link_1_v6_1.stl" scale="0.001 0.001 0.001"/>
      </geometry>
    </collision>
  </link>
  <link name="elbow_link_2_v7_1">
    <inertial>
      <origin rpy="0 0 0" xyz="0.03261486460573136 0.06783952555352685 -1.0236256287043943e-13"/>
      <mass value="1.3057586881176477"/>
      <inertia ixx="0.002958" ixy="-0.000913" ixz="0.0" iyy="0.002405" iyz="0.0" izz="0.003447"/>
    </inertial>
    <visual>
      <origin rpy="0 0 0" xyz="0.140875 0.024 -0.3167"/>
      <geometry>
        <mesh filename="package://arm_assembly_4_description/meshes/elbow_link_2_v7_1.stl" scale="0.001 0.001 0.001"/>
      </geometry>
      <material name="silver"/>
    </visual>
    <collision>
      <origin rpy="0 0 0" xyz="0.140875 0.024 -0.3167"/>
      <geometry>
        <mesh filename="package://arm_assembly_4_description/meshes/elbow_link_2_v7_1.stl" scale="0.001 0.001 0.001"/>
      </geometry>
    </collision>
  </link>
  <link name="forearm_v8_1">
    <inertial>
      <origin rpy="0 0 0" xyz="-1.249000902703301e-16 0.13257548053089302 -1.6653345369377348e-16"/>
      <mass value="1.6734453667565803"/>
      <inertia ixx="0.012845" ixy="0.0" ixz="-0.0" iyy="0.002559" iyz="0.0" izz="0.012861"/>
    </inertial>
    <visual>
      <origin rpy="0 0 0" xyz="0.091375 -0.0872 -0.3167"/>
      <geometry>
        <mesh filename="package://arm_assembly_4_description/meshes/forearm_v8_1.stl" scale="0.001 0.001 0.001"/>
      </geometry>
      <material name="silver"/>
    </visual>
    <collision>
      <origin rpy="0 0 0" xyz="0.091375 -0.0872 -0.3167"/>
      <geometry>
        <mesh filename="package://arm_assembly_4_description/meshes/forearm_v8_1.stl" scale="0.001 0.001 0.001"/>
      </geometry>
    </collision>
  </link>
  <link name="PALM_GAVIN_1DoF_Hinge_v2_1">
    <inertial>
      <origin rpy="0 0 0" xyz="-0.02233077416183611 0.05564826970859299 -0.0005939986128069008"/>
      <mass value="2.120157220826746"/>
      <inertia ixx="0.001678" ixy="-0.000146" ixz="-1.2e-05" iyy="0.001983" iyz="8e-06" izz="0.003293"/>
    </inertial>
    <visual>
      <origin rpy="0 0 0" xyz="0.066375 -0.3582 -0.3167"/>
      <geometry>
        <mesh filename="package://arm_assembly_4_description/meshes/PALM_GAVIN_1DoF_Hinge_v2_1.stl" scale="0.001 0.001 0.001"/>
      </geometry>
      <material name="silver"/>
    </visual>
    <collision>
      <origin rpy="0 0 0" xyz="0.066375 -0.3582 -0.3167"/>
      <geometry>
        <mesh filename="package://arm_assembly_4_description/meshes/PALM_GAVIN_1DoF_Hinge_v2_1.stl" scale="0.001 0.001 0.001"/>
      </geometry>
    </collision>
  </link>
  <link name="MCP_INDEX_v1_1">
    <inertial>
      <origin rpy="0 0 0" xyz="-0.005500073865622103 0.01750001303136789 -9.906511555524133e-09"/>
      <mass value="0.06647168215903997"/>
      <inertia ixx="1.1e-05" ixy="-0.0" ixz="-0.0" iyy="4e-06" iyz="-0.0" izz="1.2e-05"/>
    </inertial>
    <visual>
      <origin rpy="0 0 0" xyz="0.047125 -0.4652 -0.3172"/>
      <geometry>
        <mesh filename="package://arm_assembly_4_description/meshes/MCP_INDEX_v1_1.stl" scale="0.001 0.001 0.001"/>
      </geometry>
      <material name="silver"/>
    </visual>
    <collision>
      <origin rpy="0 0 0" xyz="0.047125 -0.4652 -0.3172"/>
      <geometry>
        <mesh filename="package://arm_assembly_4_description/meshes/MCP_INDEX_v1_1.stl" scale="0.001 0.001 0.001"/>
      </geometry>
    </collision>
  </link>
  <link name="PIP_INDEX_v1_1">
    <inertial>
      <origin rpy="0 0 0" xyz="-0.004750000108759825 0.00046534152117705396 0.015002905776295872"/>
      <mass value="0.07147211540799558"/>
      <inertia ixx="1.4e-05" ixy="0.0" ixz="-0.0" iyy="1.2e-05" iyz="-0.0" izz="3e-06"/>
    </inertial>
    <visual>
      <origin rpy="0 0 0" xyz="0.047125 -0.500608 -0.3172"/>
      <geometry>
        <mesh filename="package://arm_assembly_4_description/meshes/PIP_INDEX_v1_1.stl" scale="0.001 0.001 0.001"/>
      </geometry>
      <material name="silver"/>
    </visual>
    <collision>
      <origin rpy="0 0 0" xyz="0.047125 -0.500608 -0.3172"/>
      <geometry>
        <mesh filename="package://arm_assembly_4_description/meshes/PIP_INDEX_v1_1.stl" scale="0.001 0.001 0.001"/>
      </geometry>
    </collision>
  </link>
  <link name="DIP_INDEX_v1_1">
    <inertial>
      <origin rpy="0 0 0" xyz="0.005500032329403257 0.0015673194953499392 0.010811235762022142"/>
      <mass value="0.04298333664796617"/>
      <inertia ixx="4e-06" ixy="0.0" ixz="0.0" iyy="4e-06" iyz="-0.0" izz="2e-06"/>
    </inertial>
    <visual>
      <origin rpy="0 0 0" xyz="0.056625 -0.500608 -0.3472"/>
      <geometry>
        <mesh filename="package://arm_assembly_4_description/meshes/DIP_INDEX_v1_1.stl" scale="0.001 0.001 0.001"/>
      </geometry>
      <material name="silver"/>
    </visual>
    <collision>
      <origin rpy="0 0 0" xyz="0.056625 -0.500608 -0.3472"/>
      <geometry>
        <mesh filename="package://arm_assembly_4_description/meshes/DIP_INDEX_v1_1.stl" scale="0.001 0.001 0.001"/>
      </geometry>
    </collision>
  </link>
  <link name="MCP_MIDDLE_v1_1">
    <inertial>
      <origin rpy="0 0 0" xyz="-0.005500073865622124 0.0175000130313685 -9.906511222457226e-09"/>
      <mass value="0.06647168215903997"/>
      <inertia ixx="1.1e-05" ixy="-0.0" ixz="-0.0" iyy="4e-06" iyz="-0.0" izz="1.2e-05"/>
    </inertial>
    <visual>
      <origin rpy="0 0 0" xyz="0.073125 -0.4752 -0.3172"/>
      <geometry>
        <mesh filename="package://arm_assembly_4_description/meshes/MCP_MIDDLE_v1_1.stl" scale="0.001 0.001 0.001"/>
      </geometry>
      <material name="silver"/>
    </visual>
    <collision>
      <origin rpy="0 0 0" xyz="0.073125 -0.4752 -0.3172"/>
      <geometry>
        <mesh filename="package://arm_assembly_4_description/meshes/MCP_MIDDLE_v1_1.stl" scale="0.001 0.001 0.001"/>
      </geometry>
    </collision>
  </link>
  <link name="PIP_MIDDLE_v1_1">
    <inertial>
      <origin rpy="0 0 0" xyz="-0.004750000108759853 0.00046520863089893894 0.01500290577629615"/>
      <mass value="0.07147211540799558"/>
      <inertia ixx="1.4e-05" ixy="0.0" ixz="-0.0" iyy="1.2e-05" iyz="-0.0" izz="3e-06"/>
    </inertial>
    <visual>
      <origin rpy="0 0 0" xyz="0.073125 -0.5102 -0.3172"/>
      <geometry>
        <mesh filename="package://arm_assembly_4_description/meshes/PIP_MIDDLE_v1_1.stl" scale="0.001 0.001 0.001"/>
      </geometry>
      <material name="silver"/>
    </visual>
    <collision>
      <origin rpy="0 0 0" xyz="0.073125 -0.5102 -0.3172"/>
      <geometry>
        <mesh filename="package://arm_assembly_4_description/meshes/PIP_MIDDLE_v1_1.stl" scale="0.001 0.001 0.001"/>
      </geometry>
    </collision>
  </link>
  <link name="DIP_MIDDLE_v1_1">
    <inertial>
      <origin rpy="0 0 0" xyz="-0.005500032329402271 -0.01081123576194365 -0.0015671866049928873"/>
      <mass value="0.04298333664796617"/>
      <inertia ixx="4e-06" ixy="0.0" ixz="0.0" iyy="2e-06" iyz="-0.0" izz="4e-06"/>
    </inertial>
    <visual>
      <origin rpy="0 0 0" xyz="0.073125 -0.5102 -0.3472"/>
      <geometry>
        <mesh filename="package://arm_assembly_4_description/meshes/DIP_MIDDLE_v1_1.stl" scale="0.001 0.001 0.001"/>
      </geometry>
      <material name="silver"/>
    </visual>
    <collision>
      <origin rpy="0 0 0" xyz="0.073125 -0.5102 -0.3472"/>
      <geometry>
        <mesh filename="package://arm_assembly_4_description/meshes/DIP_MIDDLE_v1_1.stl" scale="0.001 0.001 0.001"/>
      </geometry>
    </collision>
  </link>
  <link name="MCP_RING_v1_1">
    <inertial>
      <origin rpy="0 0 0" xyz="0.0054999261343779 -9.90658988175852e-09 0.017499986968709524"/>
      <mass value="0.06647168215903997"/>
      <inertia ixx="1.1e-05" ixy="-0.0" ixz="0.0" iyy="1.2e-05" iyz="0.0" izz="4e-06"/>
    </inertial>
    <visual>
      <origin rpy="0 0 0" xyz="0.108625 -0.4652 -0.3172"/>
      <geometry>
        <mesh filename="package://arm_assembly_4_description/meshes/MCP_RING_v1_1.stl" scale="0.001 0.001 0.001"/>
      </geometry>
      <material name="silver"/>
    </visual>
    <collision>
      <origin rpy="0 0 0" xyz="0.108625 -0.4652 -0.3172"/>
      <geometry>
        <mesh filename="package://arm_assembly_4_description/meshes/MCP_RING_v1_1.stl" scale="0.001 0.001 0.001"/>
      </geometry>
    </collision>
  </link>
  <link name="PIP_RING_v1_1">
    <inertial>
      <origin rpy="0 0 0" xyz="-0.004750000108759797 0.0004652086308983283 0.015002905776295317"/>
      <mass value="0.07147211540799558"/>
      <inertia ixx="1.4e-05" ixy="0.0" ixz="-0.0" iyy="1.2e-05" iyz="-0.0" izz="3e-06"/>
    </inertial>
    <visual>
      <origin rpy="0 0 0" xyz="0.097625 -0.4652 -0.3522"/>
      <geometry>
        <mesh filename="package://arm_assembly_4_description/meshes/PIP_RING_v1_1.stl" scale="0.001 0.001 0.001"/>
      </geometry>
      <material name="silver"/>
    </visual>
    <collision>
      <origin rpy="0 0 0" xyz="0.097625 -0.4652 -0.3522"/>
      <geometry>
        <mesh filename="package://arm_assembly_4_description/meshes/PIP_RING_v1_1.stl" scale="0.001 0.001 0.001"/>
      </geometry>
    </collision>
  </link>
  <link name="DIP_RING_v1_1">
    <inertial>
      <origin rpy="0 0 0" xyz="-0.005499967670596823 0.0015671866050709915 0.010811235762021587"/>
      <mass value="0.04298333664796617"/>
      <inertia ixx="4e-06" ixy="0.0" ixz="0.0" iyy="4e-06" iyz="-0.0" izz="2e-06"/>
    </inertial>
    <visual>
      <origin rpy="0 0 0" xyz="0.097625 -0.4652 -0.3822"/>
      <geometry>
        <mesh filename="package://arm_assembly_4_description/meshes/DIP_RING_v1_1.stl" scale="0.001 0.001 0.001"/>
      </geometry>
      <material name="silver"/>
    </visual>
    <collision>
      <origin rpy="0 0 0" xyz="0.097625 -0.4652 -0.3822"/>
      <geometry>
        <mesh filename="package://arm_assembly_4_description/meshes/DIP_RING_v1_1.stl" scale="0.001 0.001 0.001"/>
      </geometry>
    </collision>
  </link>
  <link name="MCP_PINKY_v1_1">
    <inertial>
      <origin rpy="0 0 0" xyz="-0.005500073865622207 -9.906589937269672e-09 0.017499986968709635"/>
      <mass value="0.06647168215903997"/>
      <inertia ixx="1.1e-05" ixy="-0.0" ixz="0.0" iyy="1.2e-05" iyz="0.0" izz="4e-06"/>
    </inertial>
    <visual>
      <origin rpy="0 0 0" xyz="0.125125 -0.4502 -0.3172"/>
      <geometry>
        <mesh filename="package://arm_assembly_4_description/meshes/MCP_PINKY_v1_1.stl" scale="0.001 0.001 0.001"/>
      </geometry>
      <material name="silver"/>
    </visual>
    <collision>
      <origin rpy="0 0 0" xyz="0.125125 -0.4502 -0.3172"/>
      <geometry>
        <mesh filename="package://arm_assembly_4_description/meshes/MCP_PINKY_v1_1.stl" scale="0.001 0.001 0.001"/>
      </geometry>
    </collision>
  </link>
  <link name="PIP_PINKY_v1_1">
    <inertial>
      <origin rpy="0 0 0" xyz="-0.0047500001087599775 0.0004652086308981618 0.015002905776295594"/>
      <mass value="0.07147211540799558"/>
      <inertia ixx="1.4e-05" ixy="0.0" ixz="-0.0" iyy="1.2e-05" iyz="-0.0" izz="3e-06"/>
    </inertial>
    <visual>
      <origin rpy="0 0 0" xyz="0.125125 -0.4502 -0.3522"/>
      <geometry>
        <mesh filename="package://arm_assembly_4_description/meshes/PIP_PINKY_v1_1.stl" scale="0.001 0.001 0.001"/>
      </geometry>
      <material name="silver"/>
    </visual>
    <collision>
      <origin rpy="0 0 0" xyz="0.125125 -0.4502 -0.3522"/>
      <geometry>
        <mesh filename="package://arm_assembly_4_description/meshes/PIP_PINKY_v1_1.stl" scale="0.001 0.001 0.001"/>
      </geometry>
    </collision>
  </link>
  <link name="DIP_PINKY_v1_1">
    <inertial>
      <origin rpy="0 0 0" xyz="-0.005500032329402493 -0.01081123576194426 -0.0015671866049934424"/>
      <mass value="0.04298333664796617"/>
      <inertia ixx="4e-06" ixy="0.0" ixz="0.0" iyy="2e-06" iyz="-0.0" izz="4e-06"/>
    </inertial>
    <visual>
      <origin rpy="0 0 0" xyz="0.125125 -0.4502 -0.3822"/>
      <geometry>
        <mesh filename="package://arm_assembly_4_description/meshes/DIP_PINKY_v1_1.stl" scale="0.001 0.001 0.001"/>
      </geometry>
      <material name="silver"/>
    </visual>
    <collision>
      <origin rpy="0 0 0" xyz="0.125125 -0.4502 -0.3822"/>
      <geometry>
        <mesh filename="package://arm_assembly_4_description/meshes/DIP_PINKY_v1_1.stl" scale="0.001 0.001 0.001"/>
      </geometry>
    </collision>
  </link>
  <link name="CMC_THUMB_v1_1">
    <inertial>
      <origin rpy="0 0 0" xyz="0.008171816525932303 -0.014667673892031718 -0.00026820961939072463"/>
      <mass value="0.1776914594904236"/>
      <inertia ixx="2.5e-05" ixy="-5e-06" ixz="-1e-06" iyy="2.6e-05" iyz="0.0" izz="3.4e-05"/>
    </inertial>
    <visual>
      <origin rpy="0 0 0" xyz="0.046875 -0.4132 -0.3472"/>
      <geometry>
        <mesh filename="package://arm_assembly_4_description/meshes/CMC_THUMB_v1_1.stl" scale="0.001 0.001 0.001"/>
      </geometry>
      <material name="silver"/>
    </visual>
    <collision>
      <origin rpy="0 0 0" xyz="0.046875 -0.4132 -0.3472"/>
      <geometry>
        <mesh filename="package://arm_assembly_4_description/meshes/CMC_THUMB_v1_1.stl" scale="0.001 0.001 0.001"/>
      </geometry>
    </collision>
  </link>
  <link name="MCP_THUMB_v1_1">
    <inertial>
      <origin rpy="0 0 0" xyz="-0.006064265496711459 0.004028448988576683 0.013953206162800103"/>
      <mass value="0.07147211540799558"/>
      <inertia ixx="9e-06" ixy="2e-06" ixz="4e-06" iyy="1.1e-05" iyz="-3e-06" izz="8e-06"/>
    </inertial>
    <visual>
      <origin rpy="0 0 0" xyz="0.024611 -0.415171 -0.343493"/>
      <geometry>
        <mesh filename="package://arm_assembly_4_description/meshes/MCP_THUMB_v1_1.stl" scale="0.001 0.001 0.001"/>
      </geometry>
      <material name="silver"/>
    </visual>
    <collision>
      <origin rpy="0 0 0" xyz="0.024611 -0.415171 -0.343493"/>
      <geometry>
        <mesh filename="package://arm_assembly_4_description/meshes/MCP_THUMB_v1_1.stl" scale="0.001 0.001 0.001"/>
      </geometry>
    </collision>
  </link>
  <link name="IP_THUMB_v1_1">
    <inertial>
      <origin rpy="0 0 0" xyz="-0.0025155403138474933 0.002948794560108714 0.011600043359116574"/>
      <mass value="0.04298333664796617"/>
      <inertia ixx="4e-06" ixy="1e-06" ixz="1e-06" iyy="4e-06" iyz="-1e-06" izz="3e-06"/>
    </inertial>
    <visual>
      <origin rpy="0 0 0" xyz="0.042442 -0.426802 -0.36463"/>
      <geometry>
        <mesh filename="package://arm_assembly_4_description/meshes/IP_THUMB_v1_1.stl" scale="0.001 0.001 0.001"/>
      </geometry>
      <material name="silver"/>
    </visual>
    <collision>
      <origin rpy="0 0 0" xyz="0.042442 -0.426802 -0.36463"/>
      <geometry>
        <mesh filename="package://arm_assembly_4_description/meshes/IP_THUMB_v1_1.stl" scale="0.001 0.001 0.001"/>
      </geometry>
    </collision>
  </link>
  <joint name="Revolute 1" type="continuous">
    <origin rpy="0 0 0" xyz="-0.0505 0.0 0.0"/>
    <parent link="base_link"/>
    <child link="shoulder_link_1_v9_1"/>
    <axis xyz="1.0 0.0 0.0"/>
  </joint>
  <joint name="Revolute 2" type="revolute">
    <origin rpy="0 0 0" xyz="-0.065 0.0255 -0.0"/>
    <parent link="shoulder_link_1_v9_1"/>
    <child link="shoulder_link_2_v4_1"/>
    <axis xyz="0.0 -1.0 0.0"/>
    <limit effort="100" lower="-0.349066" upper="3.490659" velocity="100"/>
  </joint>
  <joint name="Revolute 3" type="continuous">
    <origin rpy="0 0 0" xyz="0.0 -0.0495 0.2112"/>
    <parent link="shoulder_link_2_v4_1"/>
    <child link="elbow_link_1_v6_1"/>
    <axis xyz="0.0 0.0 -1.0"/>
  </joint>
  <joint name="Revolute 4" type="revolute">
    <origin rpy="0 0 0" xyz="-0.025375 0.0 0.1055"/>
    <parent link="elbow_link_1_v6_1"/>
    <child link="elbow_link_2_v7_1"/>
    <axis xyz="1.0 -0.0 -0.0"/>
    <limit effort="100" lower="-0.349066" upper="3.490659" velocity="100"/>
  </joint>
  <joint name="Revolute 5" type="continuous">
    <origin rpy="0 0 0" xyz="0.0495 0.1112 0.0"/>
    <parent link="elbow_link_2_v7_1"/>
    <child link="forearm_v8_1"/>
    <axis xyz="-0.0 -1.0 0.0"/>
  </joint>
  <joint name="wrist_extension" type="revolute">
    <origin rpy="0 0 0" xyz="0.025 0.271 0.0"/>
    <parent link="forearm_v8_1"/>
    <child link="PALM_GAVIN_1DoF_Hinge_v2_1"/>
    <axis xyz="-1.0 0.0 0.0"/>
    <limit effort="100" lower="-0.959931" upper="0.959931" velocity="100"/>
  </joint>
  <joint name="mcp_index" type="revolute">
    <origin rpy="0 0 0" xyz="0.01925 0.107 0.0005"/>
    <parent link="PALM_GAVIN_1DoF_Hinge_v2_1"/>
    <child link="MCP_INDEX_v1_1"/>
    <axis xyz="-1.0 0.0 0.0"/>
    <limit effort="100" lower="-3.141593" upper="-1.570796" velocity="100"/>
  </joint>
  <joint name="Revolute 12" type="revolute">
    <origin rpy="0 0 0" xyz="0.0 0.035408 0.0"/>
    <parent link="MCP_INDEX_v1_1"/>
    <child link="PIP_INDEX_v1_1"/>
    <axis xyz="-1.0 0.0 0.0"/>
    <limit effort="100" lower="0.0" upper="1.570796" velocity="100"/>
  </joint>
  <joint name="Revolute 13" type="revolute">
    <origin rpy="0 0 0" xyz="-0.0095 0.0 0.03"/>
    <parent link="PIP_INDEX_v1_1"/>
    <child link="DIP_INDEX_v1_1"/>
    <axis xyz="-1.0 0.0 0.0"/>
    <limit effort="100" lower="-1.570796" upper="0.0" velocity="100"/>
  </joint>
  <joint name="Revolute 14" type="revolute">
    <origin rpy="0 0 0" xyz="-0.00675 0.117 0.0005"/>
    <parent link="PALM_GAVIN_1DoF_Hinge_v2_1"/>
    <child link="MCP_MIDDLE_v1_1"/>
    <axis xyz="-1.0 -0.0 0.0"/>
    <limit effort="100" lower="3.141593" upper="4.712389" velocity="100"/>
  </joint>
  <joint name="Revolute 15" type="revolute">
    <origin rpy="0 0 0" xyz="0.0 0.035 0.0"/>
    <parent link="MCP_MIDDLE_v1_1"/>
    <child link="PIP_MIDDLE_v1_1"/>
    <axis xyz="-1.0 -0.0 0.0"/>
    <limit effort="100" lower="0.0" upper="1.570796" velocity="100"/>
  </joint>
  <joint name="Revolute 16" type="revolute">
    <origin rpy="0 0 0" xyz="0.0 0.0 0.03"/>
    <parent link="PIP_MIDDLE_v1_1"/>
    <child link="DIP_MIDDLE_v1_1"/>
    <axis xyz="-1.0 -0.0 0.0"/>
    <limit effort="100" lower="1.570796" upper="3.141593" velocity="100"/>
  </joint>
  <joint name="Revolute 17" type="revolute">
    <origin rpy="0 0 0" xyz="-0.04225 0.107 0.0005"/>
    <parent link="PALM_GAVIN_1DoF_Hinge_v2_1"/>
    <child link="MCP_RING_v1_1"/>
    <axis xyz="1.0 -0.0 -0.0"/>
    <limit effort="100" lower="-1.570796" upper="0.0" velocity="100"/>
  </joint>
  <joint name="Revolute 18" type="revolute">
    <origin rpy="0 0 0" xyz="0.011 0.0 0.035"/>
    <parent link="MCP_RING_v1_1"/>
    <child link="PIP_RING_v1_1"/>
    <axis xyz="-1.0 0.0 0.0"/>
    <limit effort="100" lower="-1.570796" upper="0.0" velocity="100"/>
  </joint>
  <joint name="Revolute 19" type="continuous">
    <origin rpy="0 0 0" xyz="0.0 0.0 0.03"/>
    <parent link="PIP_RING_v1_1"/>
    <child link="DIP_RING_v1_1"/>
    <axis xyz="-1.0 0.0 0.0"/>
  </joint>
  <joint name="mcp_pinky" type="revolute">
    <origin rpy="0 0 0" xyz="-0.05875 0.092 0.0005"/>
    <parent link="PALM_GAVIN_1DoF_Hinge_v2_1"/>
    <child link="MCP_PINKY_v1_1"/>
    <axis xyz="-1.0 0.0 0.0"/>
    <limit effort="100" lower="0.0" upper="1.570796" velocity="100"/>
  </joint>
  <joint name="pip_pinky" type="revolute">
    <origin rpy="0 0 0" xyz="0.0 0.0 0.035"/>
    <parent link="MCP_PINKY_v1_1"/>
    <child link="PIP_PINKY_v1_1"/>
    <axis xyz="-1.0 0.0 0.0"/>
    <limit effort="100" lower="-1.570796" upper="0.0" velocity="100"/>
  </joint>
  <joint name="dip_pinky" type="revolute">
    <origin rpy="0 0 0" xyz="0.0 0.0 0.03"/>
    <parent link="PIP_PINKY_v1_1"/>
    <child link="DIP_PINKY_v1_1"/>
    <axis xyz="-1.0 0.0 0.0"/>
    <limit effort="100" lower="1.570796" upper="3.141593" velocity="100"/>
  </joint>
  <joint name="Revolute 23" type="continuous">
    <origin rpy="0 0 0" xyz="0.0195 0.055 0.0305"/>
    <parent link="PALM_GAVIN_1DoF_Hinge_v2_1"/>
    <child link="CMC_THUMB_v1_1"/>
    <axis xyz="-0.0 -1.0 -0.0"/>
  </joint>
  <joint name="Revolute 24" type="revolute">
    <origin rpy="0 0 0" xyz="0.022264 0.001971 -0.003707"/>
    <parent link="CMC_THUMB_v1_1"/>
    <child link="MCP_THUMB_v1_1"/>
    <axis xyz="-0.541675 0.454519 -0.707107"/>
    <limit effort="100" lower="0.785398" upper="2.530727" velocity="100"/>
  </joint>
  <joint name="Revolute 25" type="revolute">
    <origin rpy="0 0 0" xyz="-0.017831 0.011631 0.021137"/>
    <parent link="MCP_THUMB_v1_1"/>
    <child link="IP_THUMB_v1_1"/>
    <axis xyz="0.541675 -0.454519 0.707107"/>
    <limit effort="100" lower="0.0" upper="1.570796" velocity="100"/>
  </joint>
</robot>

