<?xml version='1.0' encoding='utf-8'?>
<robot name="left_arm_assembly">
  <material name="silver">
    <color rgba="0.700 0.700 0.700 1.000" />
  </material>
  <transmission name="left_shoulder_flexion_extension_tran">
    <type>transmission_interface/SimpleTransmission</type>
    <joint name="left_shoulder_flexion_extension">
      <hardwareInterface>hardware_interface/EffortJointInterface</hardwareInterface>
    </joint>
    <actuator name="left_shoulder_flexion_extension_actr">
      <hardwareInterface>hardware_interface/EffortJointInterface</hardwareInterface>
      <mechanicalReduction>1</mechanicalReduction>
    </actuator>
  </transmission>
  <transmission name="left_shoulder_abduction_adduction_tran">
    <type>transmission_interface/SimpleTransmission</type>
    <joint name="left_shoulder_abduction_adduction">
      <hardwareInterface>hardware_interface/EffortJointInterface</hardwareInterface>
    </joint>
    <actuator name="left_shoulder_abduction_adduction_actr">
      <hardwareInterface>hardware_interface/EffortJointInterface</hardwareInterface>
      <mechanicalReduction>1</mechanicalReduction>
    </actuator>
  </transmission>
  <transmission name="left_shoulder_rotation_tran">
    <type>transmission_interface/SimpleTransmission</type>
    <joint name="left_shoulder_rotation">
      <hardwareInterface>hardware_interface/EffortJointInterface</hardwareInterface>
    </joint>
    <actuator name="left_shoulder_rotation_actr">
      <hardwareInterface>hardware_interface/EffortJointInterface</hardwareInterface>
      <mechanicalReduction>1</mechanicalReduction>
    </actuator>
  </transmission>
  <transmission name="left_elbow_flexion_extension_tran">
    <type>transmission_interface/SimpleTransmission</type>
    <joint name="left_elbow_flexion_extension">
      <hardwareInterface>hardware_interface/EffortJointInterface</hardwareInterface>
    </joint>
    <actuator name="left_elbow_flexion_extension_actr">
      <hardwareInterface>hardware_interface/EffortJointInterface</hardwareInterface>
      <mechanicalReduction>1</mechanicalReduction>
    </actuator>
  </transmission>
  <transmission name="left_forearm_rotation_tran">
    <type>transmission_interface/SimpleTransmission</type>
    <joint name="left_forearm_rotation">
      <hardwareInterface>hardware_interface/EffortJointInterface</hardwareInterface>
    </joint>
    <actuator name="left_forearm_rotation_actr">
      <hardwareInterface>hardware_interface/EffortJointInterface</hardwareInterface>
      <mechanicalReduction>1</mechanicalReduction>
    </actuator>
  </transmission>
  <transmission name="left_wrist_extension_tran">
    <type>transmission_interface/SimpleTransmission</type>
    <joint name="left_wrist_extension">
      <hardwareInterface>hardware_interface/EffortJointInterface</hardwareInterface>
    </joint>
    <actuator name="left_wrist_extension_actr">
      <hardwareInterface>hardware_interface/EffortJointInterface</hardwareInterface>
      <mechanicalReduction>1</mechanicalReduction>
    </actuator>
  </transmission>
  <transmission name="left_mcp_index_tran">
    <type>transmission_interface/SimpleTransmission</type>
    <joint name="left_mcp_index">
      <hardwareInterface>hardware_interface/EffortJointInterface</hardwareInterface>
    </joint>
    <actuator name="left_mcp_index_actr">
      <hardwareInterface>hardware_interface/EffortJointInterface</hardwareInterface>
      <mechanicalReduction>1</mechanicalReduction>
    </actuator>
  </transmission>
  <transmission name="left_pip_index_tran">
    <type>transmission_interface/SimpleTransmission</type>
    <joint name="left_pip_index">
      <hardwareInterface>hardware_interface/EffortJointInterface</hardwareInterface>
    </joint>
    <actuator name="left_pip_index_actr">
      <hardwareInterface>hardware_interface/EffortJointInterface</hardwareInterface>
      <mechanicalReduction>1</mechanicalReduction>
    </actuator>
  </transmission>
  <transmission name="left_dip_index_tran">
    <type>transmission_interface/SimpleTransmission</type>
    <joint name="left_dip_index">
      <hardwareInterface>hardware_interface/EffortJointInterface</hardwareInterface>
    </joint>
    <actuator name="left_dip_index_actr">
      <hardwareInterface>hardware_interface/EffortJointInterface</hardwareInterface>
      <mechanicalReduction>1</mechanicalReduction>
    </actuator>
  </transmission>
  <transmission name="left_mcp_middle_tran">
    <type>transmission_interface/SimpleTransmission</type>
    <joint name="left_mcp_middle">
      <hardwareInterface>hardware_interface/EffortJointInterface</hardwareInterface>
    </joint>
    <actuator name="left_mcp_middle_actr">
      <hardwareInterface>hardware_interface/EffortJointInterface</hardwareInterface>
      <mechanicalReduction>1</mechanicalReduction>
    </actuator>
  </transmission>
  <transmission name="left_pip_middle_tran">
    <type>transmission_interface/SimpleTransmission</type>
    <joint name="left_pip_middle">
      <hardwareInterface>hardware_interface/EffortJointInterface</hardwareInterface>
    </joint>
    <actuator name="left_pip_middle_actr">
      <hardwareInterface>hardware_interface/EffortJointInterface</hardwareInterface>
      <mechanicalReduction>1</mechanicalReduction>
    </actuator>
  </transmission>
  <transmission name="left_dip_middle_tran">
    <type>transmission_interface/SimpleTransmission</type>
    <joint name="left_dip_middle">
      <hardwareInterface>hardware_interface/EffortJointInterface</hardwareInterface>
    </joint>
    <actuator name="left_dip_middle_actr">
      <hardwareInterface>hardware_interface/EffortJointInterface</hardwareInterface>
      <mechanicalReduction>1</mechanicalReduction>
    </actuator>
  </transmission>
  <transmission name="left_mcp_ring_tran">
    <type>transmission_interface/SimpleTransmission</type>
    <joint name="left_mcp_ring">
      <hardwareInterface>hardware_interface/EffortJointInterface</hardwareInterface>
    </joint>
    <actuator name="left_mcp_ring_actr">
      <hardwareInterface>hardware_interface/EffortJointInterface</hardwareInterface>
      <mechanicalReduction>1</mechanicalReduction>
    </actuator>
  </transmission>
  <transmission name="left_pip_ring_tran">
    <type>transmission_interface/SimpleTransmission</type>
    <joint name="left_pip_ring">
      <hardwareInterface>hardware_interface/EffortJointInterface</hardwareInterface>
    </joint>
    <actuator name="left_pip_ring_actr">
      <hardwareInterface>hardware_interface/EffortJointInterface</hardwareInterface>
      <mechanicalReduction>1</mechanicalReduction>
    </actuator>
  </transmission>
  <transmission name="left_dip_ring_tran">
    <type>transmission_interface/SimpleTransmission</type>
    <joint name="left_dip_ring">
      <hardwareInterface>hardware_interface/EffortJointInterface</hardwareInterface>
    </joint>
    <actuator name="left_dip_ring_actr">
      <hardwareInterface>hardware_interface/EffortJointInterface</hardwareInterface>
      <mechanicalReduction>1</mechanicalReduction>
    </actuator>
  </transmission>
  <transmission name="left_mcp_pinky_tran">
    <type>transmission_interface/SimpleTransmission</type>
    <joint name="left_mcp_pinky">
      <hardwareInterface>hardware_interface/EffortJointInterface</hardwareInterface>
    </joint>
    <actuator name="left_mcp_pinky_actr">
      <hardwareInterface>hardware_interface/EffortJointInterface</hardwareInterface>
      <mechanicalReduction>1</mechanicalReduction>
    </actuator>
  </transmission>
  <transmission name="left_pip_pinky_tran">
    <type>transmission_interface/SimpleTransmission</type>
    <joint name="left_pip_pinky">
      <hardwareInterface>hardware_interface/EffortJointInterface</hardwareInterface>
    </joint>
    <actuator name="left_pip_pinky_actr">
      <hardwareInterface>hardware_interface/EffortJointInterface</hardwareInterface>
      <mechanicalReduction>1</mechanicalReduction>
    </actuator>
  </transmission>
  <transmission name="left_dip_pinky_tran">
    <type>transmission_interface/SimpleTransmission</type>
    <joint name="left_dip_pinky">
      <hardwareInterface>hardware_interface/EffortJointInterface</hardwareInterface>
    </joint>
    <actuator name="left_dip_pinky_actr">
      <hardwareInterface>hardware_interface/EffortJointInterface</hardwareInterface>
      <mechanicalReduction>1</mechanicalReduction>
    </actuator>
  </transmission>
  <transmission name="left_cmc_thumb_tran">
    <type>transmission_interface/SimpleTransmission</type>
    <joint name="left_cmc_thumb">
      <hardwareInterface>hardware_interface/EffortJointInterface</hardwareInterface>
    </joint>
    <actuator name="left_cmc_thumb_actr">
      <hardwareInterface>hardware_interface/EffortJointInterface</hardwareInterface>
      <mechanicalReduction>1</mechanicalReduction>
    </actuator>
  </transmission>
  <transmission name="left_mcp_thumb_tran">
    <type>transmission_interface/SimpleTransmission</type>
    <joint name="left_mcp_thumb">
      <hardwareInterface>hardware_interface/EffortJointInterface</hardwareInterface>
    </joint>
    <actuator name="left_mcp_thumb_actr">
      <hardwareInterface>hardware_interface/EffortJointInterface</hardwareInterface>
      <mechanicalReduction>1</mechanicalReduction>
    </actuator>
  </transmission>
  <transmission name="left_ip_thumb_tran">
    <type>transmission_interface/SimpleTransmission</type>
    <joint name="left_ip_thumb">
      <hardwareInterface>hardware_interface/EffortJointInterface</hardwareInterface>
    </joint>
    <actuator name="left_ip_thumb_actr">
      <hardwareInterface>hardware_interface/EffortJointInterface</hardwareInterface>
      <mechanicalReduction>1</mechanicalReduction>
    </actuator>
  </transmission>
  <gazebo>
    <plugin filename="libgazebo_ros_control.so" name="control" />
  </gazebo>
  <gazebo reference="left_base_link">
    <material>Gazebo/Silver</material>
    <mu1>0.2</mu1>
    <mu2>0.2</mu2>
    <selfCollide>true</selfCollide>
    <gravity>true</gravity>
  </gazebo>
  <gazebo reference="left_shoulder_link_1_v9_1">
    <material>Gazebo/Silver</material>
    <mu1>0.2</mu1>
    <mu2>0.2</mu2>
    <selfCollide>true</selfCollide>
  </gazebo>
  <gazebo reference="left_shoulder_link_2_v4_1">
    <material>Gazebo/Silver</material>
    <mu1>0.2</mu1>
    <mu2>0.2</mu2>
    <selfCollide>true</selfCollide>
  </gazebo>
  <gazebo reference="left_elbow_link_1_v6_1">
    <material>Gazebo/Silver</material>
    <mu1>0.2</mu1>
    <mu2>0.2</mu2>
    <selfCollide>true</selfCollide>
  </gazebo>
  <gazebo reference="left_elbow_link_2_v7_1">
    <material>Gazebo/Silver</material>
    <mu1>0.2</mu1>
    <mu2>0.2</mu2>
    <selfCollide>true</selfCollide>
  </gazebo>
  <gazebo reference="left_forearm_v8_1">
    <material>Gazebo/Silver</material>
    <mu1>0.2</mu1>
    <mu2>0.2</mu2>
    <selfCollide>true</selfCollide>
  </gazebo>
  <gazebo reference="left_PALM_GAVIN_1DoF_Hinge_v2_1">
    <material>Gazebo/Silver</material>
    <mu1>0.2</mu1>
    <mu2>0.2</mu2>
    <selfCollide>true</selfCollide>
  </gazebo>
  <gazebo reference="left_MCP_INDEX_v1_1">
    <material>Gazebo/Silver</material>
    <mu1>0.2</mu1>
    <mu2>0.2</mu2>
    <selfCollide>true</selfCollide>
  </gazebo>
  <gazebo reference="left_PIP_INDEX_v1_1">
    <material>Gazebo/Silver</material>
    <mu1>0.2</mu1>
    <mu2>0.2</mu2>
    <selfCollide>true</selfCollide>
  </gazebo>
  <gazebo reference="left_DIP_INDEX_v1_1">
    <material>Gazebo/Silver</material>
    <mu1>0.2</mu1>
    <mu2>0.2</mu2>
    <selfCollide>true</selfCollide>
  </gazebo>
  <gazebo reference="left_MCP_MIDDLE_v1_1">
    <material>Gazebo/Silver</material>
    <mu1>0.2</mu1>
    <mu2>0.2</mu2>
    <selfCollide>true</selfCollide>
  </gazebo>
  <gazebo reference="left_PIP_MIDDLE_v1_1">
    <material>Gazebo/Silver</material>
    <mu1>0.2</mu1>
    <mu2>0.2</mu2>
    <selfCollide>true</selfCollide>
  </gazebo>
  <gazebo reference="left_DIP_MIDDLE_v1_1">
    <material>Gazebo/Silver</material>
    <mu1>0.2</mu1>
    <mu2>0.2</mu2>
    <selfCollide>true</selfCollide>
  </gazebo>
  <gazebo reference="left_MCP_RING_v1_1">
    <material>Gazebo/Silver</material>
    <mu1>0.2</mu1>
    <mu2>0.2</mu2>
    <selfCollide>true</selfCollide>
  </gazebo>
  <gazebo reference="left_PIP_RING_v1_1">
    <material>Gazebo/Silver</material>
    <mu1>0.2</mu1>
    <mu2>0.2</mu2>
    <selfCollide>true</selfCollide>
  </gazebo>
  <gazebo reference="left_DIP_RING_v1_1">
    <material>Gazebo/Silver</material>
    <mu1>0.2</mu1>
    <mu2>0.2</mu2>
    <selfCollide>true</selfCollide>
  </gazebo>
  <gazebo reference="left_MCP_PINKY_v1_1">
    <material>Gazebo/Silver</material>
    <mu1>0.2</mu1>
    <mu2>0.2</mu2>
    <selfCollide>true</selfCollide>
  </gazebo>
  <gazebo reference="left_PIP_PINKY_v1_1">
    <material>Gazebo/Silver</material>
    <mu1>0.2</mu1>
    <mu2>0.2</mu2>
    <selfCollide>true</selfCollide>
  </gazebo>
  <gazebo reference="left_DIP_PINKY_v1_1">
    <material>Gazebo/Silver</material>
    <mu1>0.2</mu1>
    <mu2>0.2</mu2>
    <selfCollide>true</selfCollide>
  </gazebo>
  <gazebo reference="left_CMC_THUMB_v1_1">
    <material>Gazebo/Silver</material>
    <mu1>0.2</mu1>
    <mu2>0.2</mu2>
    <selfCollide>true</selfCollide>
  </gazebo>
  <gazebo reference="left_MCP_THUMB_v1_1">
    <material>Gazebo/Silver</material>
    <mu1>0.2</mu1>
    <mu2>0.2</mu2>
    <selfCollide>true</selfCollide>
  </gazebo>
  <gazebo reference="left_IP_THUMB_v1_1">
    <material>Gazebo/Silver</material>
    <mu1>0.2</mu1>
    <mu2>0.2</mu2>
    <selfCollide>true</selfCollide>
  </gazebo>
  <link name="left_base_link">
    <inertial>
      <origin rpy="0 0 0" xyz="-0.0197409277044578 -1.34576736895472e-14 0.0" />
      <mass value="0.9441186699032876" />
      <inertia ixx="0.001443" ixy="0.0" ixz="0.0" iyy="0.00109" iyz="0.0" izz="0.00109" />
    </inertial>
    <visual>
      <origin rpy="0 0 0" xyz="0.0 0.0 0.0" />
      <geometry>
<<<<<<< HEAD
<<<<<<< HEAD
        <mesh filename="meshes/left_arm/left_base_link.stl" scale="0.001 0.001 0.001" />
=======
        <mesh filename="meshes/left/left_base_link.stl" scale="0.001 0.001 0.001" />
>>>>>>> ac22f6fa (new changes)
=======
        <mesh filename="meshes/left_arm/left_base_link.stl" scale="0.001 0.001 0.001" />
>>>>>>> 7d0879a4 (refactor-and-organize-assets-and-folder)
      </geometry>
      <material name="silver" />
    </visual>
    <collision>
      <origin rpy="0 0 0" xyz="0.0 0.0 0.0" />
      <geometry>
<<<<<<< HEAD
<<<<<<< HEAD
        <mesh filename="meshes/left_arm/left_base_link.stl" scale="0.001 0.001 0.001" />
=======
        <mesh filename="meshes/left/left_base_link.stl" scale="0.001 0.001 0.001" />
>>>>>>> ac22f6fa (new changes)
=======
        <mesh filename="meshes/left_arm/left_base_link.stl" scale="0.001 0.001 0.001" />
>>>>>>> 7d0879a4 (refactor-and-organize-assets-and-folder)
      </geometry>
    </collision>
  </link>
  <link name="left_shoulder_link_1_v9_1">
    <inertial>
      <origin rpy="0 0 0" xyz="-0.0577040349258761 0.00852733678900373 0.0" />
      <mass value="1.461904936741723" />
      <inertia ixx="0.00176" ixy="2.5e-05" ixz="0.0" iyy="0.002844" iyz="0.0" izz="0.002142" />
    </inertial>
    <visual>
      <origin rpy="0 0 0" xyz="0.0505 0.0 0.0" />
      <geometry>
<<<<<<< HEAD
<<<<<<< HEAD
        <mesh filename="meshes/left_arm/left_shoulder_link_1_v9_1.stl" scale="0.001 0.001 0.001" />
=======
        <mesh filename="meshes/left/left_shoulder_link_1_v9_1.stl" scale="0.001 0.001 0.001" />
>>>>>>> ac22f6fa (new changes)
=======
        <mesh filename="meshes/left_arm/left_shoulder_link_1_v9_1.stl" scale="0.001 0.001 0.001" />
>>>>>>> 7d0879a4 (refactor-and-organize-assets-and-folder)
      </geometry>
      <material name="silver" />
    </visual>
    <collision>
      <origin rpy="0 0 0" xyz="0.0505 0.0 0.0" />
      <geometry>
<<<<<<< HEAD
<<<<<<< HEAD
        <mesh filename="meshes/left_arm/left_shoulder_link_1_v9_1.stl" scale="0.001 0.001 0.001" />
=======
        <mesh filename="meshes/left/left_shoulder_link_1_v9_1.stl" scale="0.001 0.001 0.001" />
>>>>>>> ac22f6fa (new changes)
=======
        <mesh filename="meshes/left_arm/left_shoulder_link_1_v9_1.stl" scale="0.001 0.001 0.001" />
>>>>>>> 7d0879a4 (refactor-and-organize-assets-and-folder)
      </geometry>
    </collision>
  </link>
  <link name="left_shoulder_link_2_v4_1">
    <inertial>
      <origin rpy="0 0 0" xyz="-1.08246744900953e-15 0.0218219778730397 0.130757031302675" />
      <mass value="1.3282348020561616" />
      <inertia ixx="0.009192" ixy="0.0" ixz="0.0" iyy="0.008769" iyz="-0.001996" izz="0.002511" />
    </inertial>
    <visual>
      <origin rpy="0 0 0" xyz="0.1155 0.0255 0.0" />
      <geometry>
<<<<<<< HEAD
<<<<<<< HEAD
        <mesh filename="meshes/left_arm/left_shoulder_link_2_v4_1.stl" scale="0.001 0.001 0.001" />
=======
        <mesh filename="meshes/left/left_shoulder_link_2_v4_1.stl" scale="0.001 0.001 0.001" />
>>>>>>> ac22f6fa (new changes)
=======
        <mesh filename="meshes/left_arm/left_shoulder_link_2_v4_1.stl" scale="0.001 0.001 0.001" />
>>>>>>> 7d0879a4 (refactor-and-organize-assets-and-folder)
      </geometry>
      <material name="silver" />
    </visual>
    <collision>
      <origin rpy="0 0 0" xyz="0.1155 0.0255 0.0" />
      <geometry>
<<<<<<< HEAD
<<<<<<< HEAD
        <mesh filename="meshes/left_arm/left_shoulder_link_2_v4_1.stl" scale="0.001 0.001 0.001" />
=======
        <mesh filename="meshes/left/left_shoulder_link_2_v4_1.stl" scale="0.001 0.001 0.001" />
>>>>>>> ac22f6fa (new changes)
=======
        <mesh filename="meshes/left_arm/left_shoulder_link_2_v4_1.stl" scale="0.001 0.001 0.001" />
>>>>>>> 7d0879a4 (refactor-and-organize-assets-and-folder)
      </geometry>
    </collision>
  </link>
  <link name="left_elbow_link_1_v6_1">
    <inertial>
      <origin rpy="0 0 0" xyz="-7.44988342487041e-05 1.68649816334465e-14 0.0819975294541899" />
      <mass value="1.309944313217933" />
      <inertia ixx="0.003236" ixy="0.0" ixz="2e-06" iyy="0.002776" iyz="0.0" izz="0.001275" />
    </inertial>
    <visual>
      <origin rpy="0 0 0" xyz="0.1155 -0.024 -0.2112" />
      <geometry>
<<<<<<< HEAD
<<<<<<< HEAD
        <mesh filename="meshes/left_arm/left_elbow_link_1_v6_1.stl" scale="0.001 0.001 0.001" />
=======
        <mesh filename="meshes/left/left_elbow_link_1_v6_1.stl" scale="0.001 0.001 0.001" />
>>>>>>> ac22f6fa (new changes)
=======
        <mesh filename="meshes/left_arm/left_elbow_link_1_v6_1.stl" scale="0.001 0.001 0.001" />
>>>>>>> 7d0879a4 (refactor-and-organize-assets-and-folder)
      </geometry>
      <material name="silver" />
    </visual>
    <collision>
      <origin rpy="0 0 0" xyz="0.1155 -0.024 -0.2112" />
      <geometry>
<<<<<<< HEAD
<<<<<<< HEAD
        <mesh filename="meshes/left_arm/left_elbow_link_1_v6_1.stl" scale="0.001 0.001 0.001" />
=======
        <mesh filename="meshes/left/left_elbow_link_1_v6_1.stl" scale="0.001 0.001 0.001" />
>>>>>>> ac22f6fa (new changes)
=======
        <mesh filename="meshes/left_arm/left_elbow_link_1_v6_1.stl" scale="0.001 0.001 0.001" />
>>>>>>> 7d0879a4 (refactor-and-organize-assets-and-folder)
      </geometry>
    </collision>
  </link>
  <link name="left_elbow_link_2_v7_1">
    <inertial>
      <origin rpy="0 0 0" xyz="0.0326148646057314 -0.0678395255535268 -1.02362562870439e-13" />
      <mass value="1.3057586881176477" />
      <inertia ixx="0.002958" ixy="0.000913" ixz="0.0" iyy="0.002405" iyz="0.0" izz="0.003447" />
    </inertial>
    <visual>
      <origin rpy="0 0 0" xyz="0.140875 -0.024 -0.3167" />
      <geometry>
<<<<<<< HEAD
<<<<<<< HEAD
        <mesh filename="meshes/left_arm/left_elbow_link_2_v7_1.stl" scale="0.001 0.001 0.001" />
=======
        <mesh filename="meshes/left/left_elbow_link_2_v7_1.stl" scale="0.001 0.001 0.001" />
>>>>>>> ac22f6fa (new changes)
=======
        <mesh filename="meshes/left_arm/left_elbow_link_2_v7_1.stl" scale="0.001 0.001 0.001" />
>>>>>>> 7d0879a4 (refactor-and-organize-assets-and-folder)
      </geometry>
      <material name="silver" />
    </visual>
    <collision>
      <origin rpy="0 0 0" xyz="0.140875 -0.024 -0.3167" />
      <geometry>
<<<<<<< HEAD
<<<<<<< HEAD
        <mesh filename="meshes/left_arm/left_elbow_link_2_v7_1.stl" scale="0.001 0.001 0.001" />
=======
        <mesh filename="meshes/left/left_elbow_link_2_v7_1.stl" scale="0.001 0.001 0.001" />
>>>>>>> ac22f6fa (new changes)
=======
        <mesh filename="meshes/left_arm/left_elbow_link_2_v7_1.stl" scale="0.001 0.001 0.001" />
>>>>>>> 7d0879a4 (refactor-and-organize-assets-and-folder)
      </geometry>
    </collision>
  </link>
  <link name="left_forearm_v8_1">
    <inertial>
      <origin rpy="0 0 0" xyz="0.0 -0.132575480530893 0.0" />
      <mass value="1.6734453667565803" />
      <inertia ixx="0.012845" ixy="0.0" ixz="-0.0" iyy="0.002559" iyz="0.0" izz="0.012861" />
    </inertial>
    <visual>
      <origin rpy="0 0 0" xyz="0.091375 0.0872 -0.3167" />
      <geometry>
<<<<<<< HEAD
<<<<<<< HEAD
        <mesh filename="meshes/left_arm/left_forearm_v8_1.stl" scale="0.001 0.001 0.001" />
=======
        <mesh filename="meshes/left/left_forearm_v8_1.stl" scale="0.001 0.001 0.001" />
>>>>>>> ac22f6fa (new changes)
=======
        <mesh filename="meshes/left_arm/left_forearm_v8_1.stl" scale="0.001 0.001 0.001" />
>>>>>>> 7d0879a4 (refactor-and-organize-assets-and-folder)
      </geometry>
      <material name="silver" />
    </visual>
    <collision>
      <origin rpy="0 0 0" xyz="0.091375 0.0872 -0.3167" />
      <geometry>
<<<<<<< HEAD
<<<<<<< HEAD
        <mesh filename="meshes/left_arm/left_forearm_v8_1.stl" scale="0.001 0.001 0.001" />
=======
        <mesh filename="meshes/left/left_forearm_v8_1.stl" scale="0.001 0.001 0.001" />
>>>>>>> ac22f6fa (new changes)
=======
        <mesh filename="meshes/left_arm/left_forearm_v8_1.stl" scale="0.001 0.001 0.001" />
>>>>>>> 7d0879a4 (refactor-and-organize-assets-and-folder)
      </geometry>
    </collision>
  </link>
  <link name="left_PALM_GAVIN_1DoF_Hinge_v2_1">
    <inertial>
      <origin rpy="0 0 0" xyz="-0.0223307741618361 -0.055648269708593 -0.000593998612806901" />
      <mass value="2.120157220826746" />
      <inertia ixx="0.001678" ixy="0.000146" ixz="-1.2e-05" iyy="0.001983" iyz="-8e-06" izz="0.003293" />
    </inertial>
    <visual>
      <origin rpy="0 0 0" xyz="0.066375 0.3582 -0.3167" />
      <geometry>
<<<<<<< HEAD
<<<<<<< HEAD
        <mesh filename="meshes/left_arm/left_PALM_GAVIN_1DoF_Hinge_v2_1.stl" scale="0.001 0.001 0.001" />
=======
        <mesh filename="meshes/left/left_PALM_GAVIN_1DoF_Hinge_v2_1.stl" scale="0.001 0.001 0.001" />
>>>>>>> ac22f6fa (new changes)
=======
        <mesh filename="meshes/left_arm/left_PALM_GAVIN_1DoF_Hinge_v2_1.stl" scale="0.001 0.001 0.001" />
>>>>>>> 7d0879a4 (refactor-and-organize-assets-and-folder)
      </geometry>
      <material name="silver" />
    </visual>
    <collision>
      <origin rpy="0 0 0" xyz="0.066375 0.3582 -0.3167" />
      <geometry>
<<<<<<< HEAD
<<<<<<< HEAD
        <mesh filename="meshes/left_arm/left_PALM_GAVIN_1DoF_Hinge_v2_1.stl" scale="0.001 0.001 0.001" />
=======
        <mesh filename="meshes/left/left_PALM_GAVIN_1DoF_Hinge_v2_1.stl" scale="0.001 0.001 0.001" />
>>>>>>> ac22f6fa (new changes)
=======
        <mesh filename="meshes/left_arm/left_PALM_GAVIN_1DoF_Hinge_v2_1.stl" scale="0.001 0.001 0.001" />
>>>>>>> 7d0879a4 (refactor-and-organize-assets-and-folder)
      </geometry>
    </collision>
  </link>
  <link name="left_MCP_INDEX_v1_1">
    <inertial>
      <origin rpy="0 0 0" xyz="-0.0055000738656221 -0.0175000130313679 -9.90651155552413e-09" />
      <mass value="0.06647168215903997" />
      <inertia ixx="1.1e-05" ixy="0.0" ixz="-0.0" iyy="4e-06" iyz="0.0" izz="1.2e-05" />
    </inertial>
    <visual>
      <origin rpy="0 0 0" xyz="0.047125 0.4652 -0.3172" />
      <geometry>
<<<<<<< HEAD
<<<<<<< HEAD
        <mesh filename="meshes/left_arm/left_MCP_INDEX_v1_1.stl" scale="0.001 0.001 0.001" />
=======
        <mesh filename="meshes/left/left_MCP_INDEX_v1_1.stl" scale="0.001 0.001 0.001" />
>>>>>>> ac22f6fa (new changes)
=======
        <mesh filename="meshes/left_arm/left_MCP_INDEX_v1_1.stl" scale="0.001 0.001 0.001" />
>>>>>>> 7d0879a4 (refactor-and-organize-assets-and-folder)
      </geometry>
      <material name="silver" />
    </visual>
    <collision>
      <origin rpy="0 0 0" xyz="0.047125 0.4652 -0.3172" />
      <geometry>
<<<<<<< HEAD
<<<<<<< HEAD
        <mesh filename="meshes/left_arm/left_MCP_INDEX_v1_1.stl" scale="0.001 0.001 0.001" />
=======
        <mesh filename="meshes/left/left_MCP_INDEX_v1_1.stl" scale="0.001 0.001 0.001" />
>>>>>>> ac22f6fa (new changes)
=======
        <mesh filename="meshes/left_arm/left_MCP_INDEX_v1_1.stl" scale="0.001 0.001 0.001" />
>>>>>>> 7d0879a4 (refactor-and-organize-assets-and-folder)
      </geometry>
    </collision>
  </link>
  <link name="left_PIP_INDEX_v1_1">
    <inertial>
      <origin rpy="0 0 0" xyz="-0.00475000010875981 -0.000465341521177054 0.0150029057762958" />
      <mass value="0.07147211540799558" />
      <inertia ixx="1.4e-05" ixy="0.0" ixz="-0.0" iyy="1.2e-05" iyz="0.0" izz="3e-06" />
    </inertial>
    <visual>
      <origin rpy="0 0 0" xyz="0.047125 0.500608 -0.3172" />
      <geometry>
<<<<<<< HEAD
<<<<<<< HEAD
        <mesh filename="meshes/left_arm/left_PIP_INDEX_v1_1.stl" scale="0.001 0.001 0.001" />
=======
        <mesh filename="meshes/left/left_PIP_INDEX_v1_1.stl" scale="0.001 0.001 0.001" />
>>>>>>> ac22f6fa (new changes)
=======
        <mesh filename="meshes/left_arm/left_PIP_INDEX_v1_1.stl" scale="0.001 0.001 0.001" />
>>>>>>> 7d0879a4 (refactor-and-organize-assets-and-folder)
      </geometry>
      <material name="silver" />
    </visual>
    <collision>
      <origin rpy="0 0 0" xyz="0.047125 0.500608 -0.3172" />
      <geometry>
<<<<<<< HEAD
<<<<<<< HEAD
        <mesh filename="meshes/left_arm/left_PIP_INDEX_v1_1.stl" scale="0.001 0.001 0.001" />
=======
        <mesh filename="meshes/left/left_PIP_INDEX_v1_1.stl" scale="0.001 0.001 0.001" />
>>>>>>> ac22f6fa (new changes)
=======
        <mesh filename="meshes/left_arm/left_PIP_INDEX_v1_1.stl" scale="0.001 0.001 0.001" />
>>>>>>> 7d0879a4 (refactor-and-organize-assets-and-folder)
      </geometry>
    </collision>
  </link>
  <link name="left_DIP_INDEX_v1_1">
    <inertial>
      <origin rpy="0 0 0" xyz="0.00550003232940328 -0.00156731949534994 0.0108112357620221" />
      <mass value="0.04298333664796617" />
      <inertia ixx="4e-06" ixy="0.0" ixz="0.0" iyy="4e-06" iyz="0.0" izz="2e-06" />
    </inertial>
    <visual>
      <origin rpy="0 0 0" xyz="0.056625 0.500608 -0.3472" />
      <geometry>
<<<<<<< HEAD
<<<<<<< HEAD
        <mesh filename="meshes/left_arm/left_DIP_INDEX_v1_1.stl" scale="0.001 0.001 0.001" />
=======
        <mesh filename="meshes/left/left_DIP_INDEX_v1_1.stl" scale="0.001 0.001 0.001" />
>>>>>>> ac22f6fa (new changes)
=======
        <mesh filename="meshes/left_arm/left_DIP_INDEX_v1_1.stl" scale="0.001 0.001 0.001" />
>>>>>>> 7d0879a4 (refactor-and-organize-assets-and-folder)
      </geometry>
      <material name="silver" />
    </visual>
    <collision>
      <origin rpy="0 0 0" xyz="0.056625 0.500608 -0.3472" />
      <geometry>
<<<<<<< HEAD
<<<<<<< HEAD
        <mesh filename="meshes/left_arm/left_DIP_INDEX_v1_1.stl" scale="0.001 0.001 0.001" />
=======
        <mesh filename="meshes/left/left_DIP_INDEX_v1_1.stl" scale="0.001 0.001 0.001" />
>>>>>>> ac22f6fa (new changes)
=======
        <mesh filename="meshes/left_arm/left_DIP_INDEX_v1_1.stl" scale="0.001 0.001 0.001" />
>>>>>>> 7d0879a4 (refactor-and-organize-assets-and-folder)
      </geometry>
    </collision>
  </link>
  <link name="left_MCP_MIDDLE_v1_1">
    <inertial>
      <origin rpy="0 0 0" xyz="-0.00550007386562183 -0.0175000130313685 -9.90651122245723e-09" />
      <mass value="0.06647168215903997" />
      <inertia ixx="1.1e-05" ixy="0.0" ixz="-0.0" iyy="4e-06" iyz="0.0" izz="1.2e-05" />
    </inertial>
    <visual>
      <origin rpy="0 0 0" xyz="0.073125 0.4752 -0.3172" />
      <geometry>
<<<<<<< HEAD
<<<<<<< HEAD
        <mesh filename="meshes/left_arm/left_MCP_MIDDLE_v1_1.stl" scale="0.001 0.001 0.001" />
=======
        <mesh filename="meshes/left/left_MCP_MIDDLE_v1_1.stl" scale="0.001 0.001 0.001" />
>>>>>>> ac22f6fa (new changes)
=======
        <mesh filename="meshes/left_arm/left_MCP_MIDDLE_v1_1.stl" scale="0.001 0.001 0.001" />
>>>>>>> 7d0879a4 (refactor-and-organize-assets-and-folder)
      </geometry>
      <material name="silver" />
    </visual>
    <collision>
      <origin rpy="0 0 0" xyz="0.073125 0.4752 -0.3172" />
      <geometry>
<<<<<<< HEAD
<<<<<<< HEAD
        <mesh filename="meshes/left_arm/left_MCP_MIDDLE_v1_1.stl" scale="0.001 0.001 0.001" />
=======
        <mesh filename="meshes/left/left_MCP_MIDDLE_v1_1.stl" scale="0.001 0.001 0.001" />
>>>>>>> ac22f6fa (new changes)
=======
        <mesh filename="meshes/left_arm/left_MCP_MIDDLE_v1_1.stl" scale="0.001 0.001 0.001" />
>>>>>>> 7d0879a4 (refactor-and-organize-assets-and-folder)
      </geometry>
    </collision>
  </link>
  <link name="left_PIP_MIDDLE_v1_1">
    <inertial>
      <origin rpy="0 0 0" xyz="-0.00475000010875959 -0.000465208630898939 0.0150029057762961" />
      <mass value="0.07147211540799558" />
      <inertia ixx="1.4e-05" ixy="0.0" ixz="-0.0" iyy="1.2e-05" iyz="0.0" izz="3e-06" />
    </inertial>
    <visual>
      <origin rpy="0 0 0" xyz="0.073125 0.5102 -0.3172" />
      <geometry>
<<<<<<< HEAD
<<<<<<< HEAD
        <mesh filename="meshes/left_arm/left_PIP_MIDDLE_v1_1.stl" scale="0.001 0.001 0.001" />
=======
        <mesh filename="meshes/left/left_PIP_MIDDLE_v1_1.stl" scale="0.001 0.001 0.001" />
>>>>>>> ac22f6fa (new changes)
=======
        <mesh filename="meshes/left_arm/left_PIP_MIDDLE_v1_1.stl" scale="0.001 0.001 0.001" />
>>>>>>> 7d0879a4 (refactor-and-organize-assets-and-folder)
      </geometry>
      <material name="silver" />
    </visual>
    <collision>
      <origin rpy="0 0 0" xyz="0.073125 0.5102 -0.3172" />
      <geometry>
<<<<<<< HEAD
<<<<<<< HEAD
        <mesh filename="meshes/left_arm/left_PIP_MIDDLE_v1_1.stl" scale="0.001 0.001 0.001" />
=======
        <mesh filename="meshes/left/left_PIP_MIDDLE_v1_1.stl" scale="0.001 0.001 0.001" />
>>>>>>> ac22f6fa (new changes)
=======
        <mesh filename="meshes/left_arm/left_PIP_MIDDLE_v1_1.stl" scale="0.001 0.001 0.001" />
>>>>>>> 7d0879a4 (refactor-and-organize-assets-and-folder)
      </geometry>
    </collision>
  </link>
  <link name="left_DIP_MIDDLE_v1_1">
    <inertial>
      <origin rpy="0 0 0" xyz="0.00550003232940346 0.0108112357619435 0.00156718660514987" />
      <mass value="0.04298333664796617" />
      <inertia ixx="4e-06" ixy="0.0" ixz="0.0" iyy="2e-06" iyz="0.0" izz="4e-06" />
    </inertial>
    <visual>
      <origin rpy="0 0 0" xyz="0.082625 0.5102 -0.3472" />
      <geometry>
<<<<<<< HEAD
<<<<<<< HEAD
        <mesh filename="meshes/left_arm/left_DIP_MIDDLE_v1_1.stl" scale="0.001 0.001 0.001" />
=======
        <mesh filename="meshes/left/left_DIP_MIDDLE_v1_1.stl" scale="0.001 0.001 0.001" />
>>>>>>> ac22f6fa (new changes)
=======
        <mesh filename="meshes/left_arm/left_DIP_MIDDLE_v1_1.stl" scale="0.001 0.001 0.001" />
>>>>>>> 7d0879a4 (refactor-and-organize-assets-and-folder)
      </geometry>
      <material name="silver" />
    </visual>
    <collision>
      <origin rpy="0 0 0" xyz="0.082625 0.5102 -0.3472" />
      <geometry>
<<<<<<< HEAD
<<<<<<< HEAD
        <mesh filename="meshes/left_arm/left_DIP_MIDDLE_v1_1.stl" scale="0.001 0.001 0.001" />
=======
        <mesh filename="meshes/left/left_DIP_MIDDLE_v1_1.stl" scale="0.001 0.001 0.001" />
>>>>>>> ac22f6fa (new changes)
=======
        <mesh filename="meshes/left_arm/left_DIP_MIDDLE_v1_1.stl" scale="0.001 0.001 0.001" />
>>>>>>> 7d0879a4 (refactor-and-organize-assets-and-folder)
      </geometry>
    </collision>
  </link>
  <link name="left_MCP_RING_v1_1">
    <inertial>
      <origin rpy="0 0 0" xyz="0.0054999261343779 9.90658988175852e-09 0.0174999869687095" />
      <mass value="0.06647168215903997" />
      <inertia ixx="1.1e-05" ixy="0.0" ixz="0.0" iyy="1.2e-05" iyz="0.0" izz="4e-06" />
    </inertial>
    <visual>
      <origin rpy="0 0 0" xyz="0.108625 0.4652 -0.3172" />
      <geometry>
<<<<<<< HEAD
<<<<<<< HEAD
        <mesh filename="meshes/left_arm/left_MCP_RING_v1_1.stl" scale="0.001 0.001 0.001" />
=======
        <mesh filename="meshes/left/left_MCP_RING_v1_1.stl" scale="0.001 0.001 0.001" />
>>>>>>> ac22f6fa (new changes)
=======
        <mesh filename="meshes/left_arm/left_MCP_RING_v1_1.stl" scale="0.001 0.001 0.001" />
>>>>>>> 7d0879a4 (refactor-and-organize-assets-and-folder)
      </geometry>
      <material name="silver" />
    </visual>
    <collision>
      <origin rpy="0 0 0" xyz="0.108625 0.4652 -0.3172" />
      <geometry>
<<<<<<< HEAD
<<<<<<< HEAD
        <mesh filename="meshes/left_arm/left_MCP_RING_v1_1.stl" scale="0.001 0.001 0.001" />
=======
        <mesh filename="meshes/left/left_MCP_RING_v1_1.stl" scale="0.001 0.001 0.001" />
>>>>>>> ac22f6fa (new changes)
=======
        <mesh filename="meshes/left_arm/left_MCP_RING_v1_1.stl" scale="0.001 0.001 0.001" />
>>>>>>> 7d0879a4 (refactor-and-organize-assets-and-folder)
      </geometry>
    </collision>
  </link>
  <link name="left_PIP_RING_v1_1">
    <inertial>
      <origin rpy="0 0 0" xyz="-0.0047500001087598 -0.000465208630898328 0.0150029057762953" />
      <mass value="0.07147211540799558" />
      <inertia ixx="1.4e-05" ixy="0.0" ixz="-0.0" iyy="1.2e-05" iyz="0.0" izz="3e-06" />
    </inertial>
    <visual>
      <origin rpy="0 0 0" xyz="0.097625 0.4652 -0.3522" />
      <geometry>
<<<<<<< HEAD
<<<<<<< HEAD
        <mesh filename="meshes/left_arm/left_PIP_RING_v1_1.stl" scale="0.001 0.001 0.001" />
=======
        <mesh filename="meshes/left/left_PIP_RING_v1_1.stl" scale="0.001 0.001 0.001" />
>>>>>>> ac22f6fa (new changes)
=======
        <mesh filename="meshes/left_arm/left_PIP_RING_v1_1.stl" scale="0.001 0.001 0.001" />
>>>>>>> 7d0879a4 (refactor-and-organize-assets-and-folder)
      </geometry>
      <material name="silver" />
    </visual>
    <collision>
      <origin rpy="0 0 0" xyz="0.097625 0.4652 -0.3522" />
      <geometry>
<<<<<<< HEAD
<<<<<<< HEAD
        <mesh filename="meshes/left_arm/left_PIP_RING_v1_1.stl" scale="0.001 0.001 0.001" />
=======
        <mesh filename="meshes/left/left_PIP_RING_v1_1.stl" scale="0.001 0.001 0.001" />
>>>>>>> ac22f6fa (new changes)
=======
        <mesh filename="meshes/left_arm/left_PIP_RING_v1_1.stl" scale="0.001 0.001 0.001" />
>>>>>>> 7d0879a4 (refactor-and-organize-assets-and-folder)
      </geometry>
    </collision>
  </link>
  <link name="left_DIP_RING_v1_1">
    <inertial>
      <origin rpy="0 0 0" xyz="-0.00549996767059682 -0.00156718660507099 0.0108112357620218" />
      <mass value="0.04298333664796617" />
      <inertia ixx="4e-06" ixy="0.0" ixz="0.0" iyy="4e-06" iyz="0.0" izz="2e-06" />
    </inertial>
    <visual>
      <origin rpy="0 0 0" xyz="0.097625 0.4652 -0.3822" />
      <geometry>
<<<<<<< HEAD
<<<<<<< HEAD
        <mesh filename="meshes/left_arm/left_DIP_RING_v1_1.stl" scale="0.001 0.001 0.001" />
=======
        <mesh filename="meshes/left/left_DIP_RING_v1_1.stl" scale="0.001 0.001 0.001" />
>>>>>>> ac22f6fa (new changes)
=======
        <mesh filename="meshes/left_arm/left_DIP_RING_v1_1.stl" scale="0.001 0.001 0.001" />
>>>>>>> 7d0879a4 (refactor-and-organize-assets-and-folder)
      </geometry>
      <material name="silver" />
    </visual>
    <collision>
      <origin rpy="0 0 0" xyz="0.097625 0.4652 -0.3822" />
      <geometry>
<<<<<<< HEAD
<<<<<<< HEAD
        <mesh filename="meshes/left_arm/left_DIP_RING_v1_1.stl" scale="0.001 0.001 0.001" />
=======
        <mesh filename="meshes/left/left_DIP_RING_v1_1.stl" scale="0.001 0.001 0.001" />
>>>>>>> ac22f6fa (new changes)
=======
        <mesh filename="meshes/left_arm/left_DIP_RING_v1_1.stl" scale="0.001 0.001 0.001" />
>>>>>>> 7d0879a4 (refactor-and-organize-assets-and-folder)
      </geometry>
    </collision>
  </link>
  <link name="left_MCP_PINKY_v1_1">
    <inertial>
      <origin rpy="0 0 0" xyz="-0.00550007386562218 9.90658993726967e-09 0.0174999869687096" />
      <mass value="0.06647168215903997" />
      <inertia ixx="1.1e-05" ixy="0.0" ixz="0.0" iyy="1.2e-05" iyz="0.0" izz="4e-06" />
    </inertial>
    <visual>
      <origin rpy="0 0 0" xyz="0.125125 0.4502 -0.3172" />
      <geometry>
<<<<<<< HEAD
<<<<<<< HEAD
        <mesh filename="meshes/left_arm/left_MCP_PINKY_v1_1.stl" scale="0.001 0.001 0.001" />
=======
        <mesh filename="meshes/left/left_MCP_PINKY_v1_1.stl" scale="0.001 0.001 0.001" />
>>>>>>> ac22f6fa (new changes)
=======
        <mesh filename="meshes/left_arm/left_MCP_PINKY_v1_1.stl" scale="0.001 0.001 0.001" />
>>>>>>> 7d0879a4 (refactor-and-organize-assets-and-folder)
      </geometry>
      <material name="silver" />
    </visual>
    <collision>
      <origin rpy="0 0 0" xyz="0.125125 0.4502 -0.3172" />
      <geometry>
<<<<<<< HEAD
<<<<<<< HEAD
        <mesh filename="meshes/left_arm/left_MCP_PINKY_v1_1.stl" scale="0.001 0.001 0.001" />
=======
        <mesh filename="meshes/left/left_MCP_PINKY_v1_1.stl" scale="0.001 0.001 0.001" />
>>>>>>> ac22f6fa (new changes)
=======
        <mesh filename="meshes/left_arm/left_MCP_PINKY_v1_1.stl" scale="0.001 0.001 0.001" />
>>>>>>> 7d0879a4 (refactor-and-organize-assets-and-folder)
      </geometry>
    </collision>
  </link>
  <link name="left_PIP_PINKY_v1_1">
    <inertial>
      <origin rpy="0 0 0" xyz="-0.00475000010875989 -0.000465208630898051 0.0150029057762957" />
      <mass value="0.07147211540799558" />
      <inertia ixx="1.4e-05" ixy="0.0" ixz="-0.0" iyy="1.2e-05" iyz="0.0" izz="3e-06" />
    </inertial>
    <visual>
      <origin rpy="0 0 0" xyz="0.125125 0.4502 -0.3522" />
      <geometry>
<<<<<<< HEAD
<<<<<<< HEAD
        <mesh filename="meshes/left_arm/left_PIP_PINKY_v1_1.stl" scale="0.001 0.001 0.001" />
=======
        <mesh filename="meshes/left/left_PIP_PINKY_v1_1.stl" scale="0.001 0.001 0.001" />
>>>>>>> ac22f6fa (new changes)
=======
        <mesh filename="meshes/left_arm/left_PIP_PINKY_v1_1.stl" scale="0.001 0.001 0.001" />
>>>>>>> 7d0879a4 (refactor-and-organize-assets-and-folder)
      </geometry>
      <material name="silver" />
    </visual>
    <collision>
      <origin rpy="0 0 0" xyz="0.125125 0.4502 -0.3522" />
      <geometry>
<<<<<<< HEAD
<<<<<<< HEAD
        <mesh filename="meshes/left_arm/left_PIP_PINKY_v1_1.stl" scale="0.001 0.001 0.001" />
=======
        <mesh filename="meshes/left/left_PIP_PINKY_v1_1.stl" scale="0.001 0.001 0.001" />
>>>>>>> ac22f6fa (new changes)
=======
        <mesh filename="meshes/left_arm/left_PIP_PINKY_v1_1.stl" scale="0.001 0.001 0.001" />
>>>>>>> 7d0879a4 (refactor-and-organize-assets-and-folder)
      </geometry>
    </collision>
  </link>
  <link name="left_DIP_PINKY_v1_1">
    <inertial>
      <origin rpy="0 0 0" xyz="0.00550003232940313 0.0108112357619443 0.00156718660514954" />
      <mass value="0.04298333664796617" />
      <inertia ixx="4e-06" ixy="0.0" ixz="0.0" iyy="2e-06" iyz="0.0" izz="4e-06" />
    </inertial>
    <visual>
      <origin rpy="0 0 0" xyz="0.134625 0.4502 -0.3822" />
      <geometry>
<<<<<<< HEAD
<<<<<<< HEAD
        <mesh filename="meshes/left_arm/left_DIP_PINKY_v1_1.stl" scale="0.001 0.001 0.001" />
=======
        <mesh filename="meshes/left/left_DIP_PINKY_v1_1.stl" scale="0.001 0.001 0.001" />
>>>>>>> ac22f6fa (new changes)
=======
        <mesh filename="meshes/left_arm/left_DIP_PINKY_v1_1.stl" scale="0.001 0.001 0.001" />
>>>>>>> 7d0879a4 (refactor-and-organize-assets-and-folder)
      </geometry>
      <material name="silver" />
    </visual>
    <collision>
      <origin rpy="0 0 0" xyz="0.134625 0.4502 -0.3822" />
      <geometry>
<<<<<<< HEAD
<<<<<<< HEAD
        <mesh filename="meshes/left_arm/left_DIP_PINKY_v1_1.stl" scale="0.001 0.001 0.001" />
=======
        <mesh filename="meshes/left/left_DIP_PINKY_v1_1.stl" scale="0.001 0.001 0.001" />
>>>>>>> ac22f6fa (new changes)
=======
        <mesh filename="meshes/left_arm/left_DIP_PINKY_v1_1.stl" scale="0.001 0.001 0.001" />
>>>>>>> 7d0879a4 (refactor-and-organize-assets-and-folder)
      </geometry>
    </collision>
  </link>
  <link name="left_CMC_THUMB_v1_1">
    <inertial>
      <origin rpy="0 0 0" xyz="0.0081718165259323 0.0146676738920317 -0.000268209619390725" />
      <mass value="0.1776914594904236" />
      <inertia ixx="2.5e-05" ixy="5e-06" ixz="-1e-06" iyy="2.6e-05" iyz="0.0" izz="3.4e-05" />
    </inertial>
    <visual>
      <origin rpy="0 0 0" xyz="0.046875 0.4132 -0.3472" />
      <geometry>
<<<<<<< HEAD
<<<<<<< HEAD
        <mesh filename="meshes/left_arm/left_CMC_THUMB_v1_1.stl" scale="0.001 0.001 0.001" />
=======
        <mesh filename="meshes/left/left_CMC_THUMB_v1_1.stl" scale="0.001 0.001 0.001" />
>>>>>>> ac22f6fa (new changes)
=======
        <mesh filename="meshes/left_arm/left_CMC_THUMB_v1_1.stl" scale="0.001 0.001 0.001" />
>>>>>>> 7d0879a4 (refactor-and-organize-assets-and-folder)
      </geometry>
      <material name="silver" />
    </visual>
    <collision>
      <origin rpy="0 0 0" xyz="0.046875 0.4132 -0.3472" />
      <geometry>
<<<<<<< HEAD
<<<<<<< HEAD
        <mesh filename="meshes/left_arm/left_CMC_THUMB_v1_1.stl" scale="0.001 0.001 0.001" />
=======
        <mesh filename="meshes/left/left_CMC_THUMB_v1_1.stl" scale="0.001 0.001 0.001" />
>>>>>>> ac22f6fa (new changes)
=======
        <mesh filename="meshes/left_arm/left_CMC_THUMB_v1_1.stl" scale="0.001 0.001 0.001" />
>>>>>>> 7d0879a4 (refactor-and-organize-assets-and-folder)
      </geometry>
    </collision>
  </link>
  <link name="left_MCP_THUMB_v1_1">
    <inertial>
      <origin rpy="0 0 0" xyz="-0.00606426549671146 -0.00402844898857668 0.0139532061628001" />
      <mass value="0.07147211540799558" />
      <inertia ixx="9e-06" ixy="-2e-06" ixz="4e-06" iyy="1.1e-05" iyz="3e-06" izz="8e-06" />
    </inertial>
    <visual>
      <origin rpy="0 0 0" xyz="0.024611 0.415171 -0.343493" />
      <geometry>
<<<<<<< HEAD
<<<<<<< HEAD
        <mesh filename="meshes/left_arm/left_MCP_THUMB_v1_1.stl" scale="0.001 0.001 0.001" />
=======
        <mesh filename="meshes/left/left_MCP_THUMB_v1_1.stl" scale="0.001 0.001 0.001" />
>>>>>>> ac22f6fa (new changes)
=======
        <mesh filename="meshes/left_arm/left_MCP_THUMB_v1_1.stl" scale="0.001 0.001 0.001" />
>>>>>>> 7d0879a4 (refactor-and-organize-assets-and-folder)
      </geometry>
      <material name="silver" />
    </visual>
    <collision>
      <origin rpy="0 0 0" xyz="0.024611 0.415171 -0.343493" />
      <geometry>
<<<<<<< HEAD
<<<<<<< HEAD
        <mesh filename="meshes/left_arm/left_MCP_THUMB_v1_1.stl" scale="0.001 0.001 0.001" />
=======
        <mesh filename="meshes/left/left_MCP_THUMB_v1_1.stl" scale="0.001 0.001 0.001" />
>>>>>>> ac22f6fa (new changes)
=======
        <mesh filename="meshes/left_arm/left_MCP_THUMB_v1_1.stl" scale="0.001 0.001 0.001" />
>>>>>>> 7d0879a4 (refactor-and-organize-assets-and-folder)
      </geometry>
    </collision>
  </link>
  <link name="left_IP_THUMB_v1_1">
    <inertial>
      <origin rpy="0 0 0" xyz="-0.00251554031384749 -0.00294879456010871 0.0116000433591166" />
      <mass value="0.04298333664796617" />
      <inertia ixx="4e-06" ixy="-1e-06" ixz="1e-06" iyy="4e-06" iyz="1e-06" izz="3e-06" />
    </inertial>
    <visual>
      <origin rpy="0 0 0" xyz="0.042442 0.426802 -0.36463" />
      <geometry>
<<<<<<< HEAD
<<<<<<< HEAD
        <mesh filename="meshes/left_arm/left_IP_THUMB_v1_1.stl" scale="0.001 0.001 0.001" />
=======
        <mesh filename="meshes/left/left_IP_THUMB_v1_1.stl" scale="0.001 0.001 0.001" />
>>>>>>> ac22f6fa (new changes)
=======
        <mesh filename="meshes/left_arm/left_IP_THUMB_v1_1.stl" scale="0.001 0.001 0.001" />
>>>>>>> 7d0879a4 (refactor-and-organize-assets-and-folder)
      </geometry>
      <material name="silver" />
    </visual>
    <collision>
      <origin rpy="0 0 0" xyz="0.042442 0.426802 -0.36463" />
      <geometry>
<<<<<<< HEAD
<<<<<<< HEAD
        <mesh filename="meshes/left_arm/left_IP_THUMB_v1_1.stl" scale="0.001 0.001 0.001" />
=======
        <mesh filename="meshes/left/left_IP_THUMB_v1_1.stl" scale="0.001 0.001 0.001" />
>>>>>>> ac22f6fa (new changes)
=======
        <mesh filename="meshes/left_arm/left_IP_THUMB_v1_1.stl" scale="0.001 0.001 0.001" />
>>>>>>> 7d0879a4 (refactor-and-organize-assets-and-folder)
      </geometry>
    </collision>
  </link>
  <joint name="left_shoulder_flexion_extension" type="continuous">
    <origin rpy="0 0 0" xyz="-0.0505 0.0 0.0" />
    <parent link="left_base_link" />
    <child link="left_shoulder_link_1_v9_1" />
    <axis xyz="-1 0.0 0.0" />
  </joint>
  <joint name="left_shoulder_abduction_adduction" type="revolute">
    <origin rpy="0 0 0" xyz="-0.065 -0.0255 0.0" />
    <parent link="left_shoulder_link_1_v9_1" />
    <child link="left_shoulder_link_2_v4_1" />
    <axis xyz="0.0 -1 0.0" />
    <limit effort="100" lower="-0.349066" upper="3.490659" velocity="100" />
  </joint>
  <joint name="left_shoulder_rotation" type="continuous">
    <origin rpy="0 0 0" xyz="0.0 0.0495 0.2112" />
    <parent link="left_shoulder_link_2_v4_1" />
    <child link="left_elbow_link_1_v6_1" />
    <axis xyz="0.0 0.0 1" />
  </joint>
  <joint name="left_elbow_flexion_extension" type="revolute">
    <origin rpy="0 0 0" xyz="-0.025375 0.0 0.1055" />
    <parent link="left_elbow_link_1_v6_1" />
    <child link="left_elbow_link_2_v7_1" />
    <axis xyz="-1 0.0 0.0" />
    <limit effort="100" lower="-0.349066" upper="3.490659" velocity="100" />
  </joint>
  <joint name="left_forearm_rotation" type="revolute">
    <origin rpy="0 0 0" xyz="0.0495 -0.1112 0.0" />
    <parent link="left_elbow_link_2_v7_1" />
    <child link="left_forearm_v8_1" />
    <axis xyz="0.0 -1 0.0" />
    <limit effort="100" lower="0.0" upper="3.14" velocity="100" />
  </joint>
  <joint name="left_wrist_extension" type="revolute">
    <origin rpy="0 0 0" xyz="0.025 -0.271 0.0" />
    <parent link="left_forearm_v8_1" />
    <child link="left_PALM_GAVIN_1DoF_Hinge_v2_1" />
    <axis xyz="1 0.0 0.0" />
    <limit effort="100" lower="-0.959931" upper="0.959931" velocity="100" />
  </joint>
  <joint name="left_mcp_index" type="revolute">
    <origin rpy="0 0 0" xyz="0.01925 -0.107 0.0005" />
    <parent link="left_PALM_GAVIN_1DoF_Hinge_v2_1" />
    <child link="left_MCP_INDEX_v1_1" />
    <axis xyz="1 0.0 0.0" />
    <limit effort="100" lower="-1.570796" upper="0.0" velocity="100" />
  </joint>
  <joint name="left_pip_index" type="revolute">
    <origin rpy="0 0 0" xyz="0.0 -0.035408 0.0" />
    <parent link="left_MCP_INDEX_v1_1" />
    <child link="left_PIP_INDEX_v1_1" />
    <axis xyz="1 0.0 0.0" />
    <limit effort="100" lower="0.0" upper="1.570796" velocity="100" />
  </joint>
  <joint name="left_dip_index" type="revolute">
    <origin rpy="0 0 0" xyz="-0.0095 0.0 0.03" />
    <parent link="left_PIP_INDEX_v1_1" />
    <child link="left_DIP_INDEX_v1_1" />
    <axis xyz="1 0.0 0.0" />
    <limit effort="100" lower="-1.570796" upper="0.0" velocity="100" />
  </joint>
  <joint name="left_mcp_middle" type="revolute">
    <origin rpy="0 0 0" xyz="-0.00675 -0.117 0.0005" />
    <parent link="left_PALM_GAVIN_1DoF_Hinge_v2_1" />
    <child link="left_MCP_MIDDLE_v1_1" />
    <axis xyz="1 0.0 0.0" />
    <limit effort="100" lower="-1.570796" upper="0.0" velocity="100" />
  </joint>
  <joint name="left_pip_middle" type="revolute">
    <origin rpy="0 0 0" xyz="0.0 -0.035 0.0" />
    <parent link="left_MCP_MIDDLE_v1_1" />
    <child link="left_PIP_MIDDLE_v1_1" />
    <axis xyz="1 0.0 0.0" />
    <limit effort="100" lower="0.0" upper="1.570796" velocity="100" />
  </joint>
  <joint name="left_dip_middle" type="revolute">
    <origin rpy="0 0 0" xyz="-0.0095 0.0 0.03" />
    <parent link="left_PIP_MIDDLE_v1_1" />
    <child link="left_DIP_MIDDLE_v1_1" />
    <axis xyz="1 0.0 0.0" />
    <limit effort="100" lower="0.0" upper="1.570796" velocity="100" />
  </joint>
  <joint name="left_mcp_ring" type="revolute">
    <origin rpy="0 0 0" xyz="-0.04225 -0.107 0.0005" />
    <parent link="left_PALM_GAVIN_1DoF_Hinge_v2_1" />
    <child link="left_MCP_RING_v1_1" />
    <axis xyz="1 0.0 0.0" />
    <limit effort="100" lower="0.0" upper="1.570796" velocity="100" />
  </joint>
  <joint name="left_pip_ring" type="revolute">
    <origin rpy="0 0 0" xyz="0.011 0.0 0.035" />
    <parent link="left_MCP_RING_v1_1" />
    <child link="left_PIP_RING_v1_1" />
    <axis xyz="1 0.0 0.0" />
    <limit effort="100" lower="-1.570796" upper="0.0" velocity="100" />
  </joint>
  <joint name="left_dip_ring" type="revolute">
    <origin rpy="0 0 0" xyz="0.0 0.0 0.03" />
    <parent link="left_PIP_RING_v1_1" />
    <child link="left_DIP_RING_v1_1" />
    <axis xyz="1 0.0 0.0" />
    <limit effort="100" lower="-1.570796" upper="0.0" velocity="100" />
  </joint>
  <joint name="left_mcp_pinky" type="revolute">
    <origin rpy="0 0 0" xyz="-0.05875 -0.092 0.0005" />
    <parent link="left_PALM_GAVIN_1DoF_Hinge_v2_1" />
    <child link="left_MCP_PINKY_v1_1" />
    <axis xyz="1 0.0 0.0" />
    <limit effort="100" lower="0.0" upper="1.570796" velocity="100" />
  </joint>
  <joint name="left_pip_pinky" type="revolute">
    <origin rpy="0 0 0" xyz="0.0 0.0 0.035" />
    <parent link="left_MCP_PINKY_v1_1" />
    <child link="left_PIP_PINKY_v1_1" />
    <axis xyz="1 0.0 0.0" />
    <limit effort="100" lower="-1.570796" upper="0.0" velocity="100" />
  </joint>
  <joint name="left_dip_pinky" type="revolute">
    <origin rpy="0 0 0" xyz="-0.0095 0.0 0.03" />
    <parent link="left_PIP_PINKY_v1_1" />
    <child link="left_DIP_PINKY_v1_1" />
    <axis xyz="1 0.0 0.0" />
    <limit effort="100" lower="0.0" upper="1.570796" velocity="100" />
  </joint>
  <joint name="left_cmc_thumb" type="revolute">
    <origin rpy="0 0 0" xyz="0.0195 -0.055 0.0305" />
    <parent link="left_PALM_GAVIN_1DoF_Hinge_v2_1" />
    <child link="left_CMC_THUMB_v1_1" />
    <axis xyz="0.0 -1 0.0" />
    <limit effort="100" lower="-0.349066" upper="2.094395" velocity="100" />
  </joint>
  <joint name="left_mcp_thumb" type="revolute">
    <origin rpy="0 0 0" xyz="0.022264 -0.001971 -0.003707" />
    <parent link="left_CMC_THUMB_v1_1" />
    <child link="left_MCP_THUMB_v1_1" />
    <axis xyz="0.541675 0.454519 0.707107" />
    <limit effort="100" lower="0.785398" upper="2.530727" velocity="100" />
  </joint>
  <joint name="left_ip_thumb" type="revolute">
    <origin rpy="0 0 0" xyz="-0.017831 -0.011631 0.021137" />
    <parent link="left_MCP_THUMB_v1_1" />
    <child link="left_IP_THUMB_v1_1" />
    <axis xyz="-0.541675 -0.454519 -0.707107" />
    <limit effort="100" lower="0.0" upper="1.570796" velocity="100" />
  </joint>
</robot>