<?xml version="1.0" encoding="utf-8"?>
<!-- This URDF was automatically created by SolidWorks to URDF Exporter! Originally created by Stephen Brawner (brawner@gmail.com) 
     Commit Version: 1.6.0-4-g7f85cfe  Build Version: 1.6.7995.38578
     For more information, please see http://wiki.ros.org/sw_urdf_exporter -->
<robot
  name="hand_urdf">
  <link
    name="hand_origin">
    <inertial>
      <origin
        xyz="0.012639008388684 0.0549439388053319 0.0177667423083054"
        rpy="0 0 0" />
      <mass
        value="0.0660106439932599" />
      <inertia
        ixx="5.23782502756952E-05"
        ixy="5.56027503556311E-06"
        ixz="-2.04232704241116E-06"
        iyy="4.68435144724578E-05"
        iyz="-3.53759019318885E-06"
        izz="9.33111093969451E-05" />
    </inertial>
    <visual>
      <origin
        xyz="0 0 0"
        rpy="0 0 0" />
      <geometry>
        <mesh
          filename="../meshes/hand_origin.STL" />
      </geometry>
      <material
        name="">
        <color
          rgba="0.792156862745098 0.819607843137255 0.933333333333333 1" />
      </material>
    </visual>
    <collision>
      <origin
        xyz="0 0 0"
        rpy="0 0 0" />
      <geometry>
        <mesh
          filename="../meshes/hand_origin.STL" />
      </geometry>
    </collision>
  </link>
  <link
    name="thumb">
    <inertial>
      <origin
        xyz="-0.00410792155457581 -0.023660585810971 -0.0137428432395027"
        rpy="0 0 0" />
      <mass
        value="0.00587030274151416" />
      <inertia
        ixx="2.11945982245643E-06"
        ixy="-1.30096195547478E-07"
        ixz="3.98749006866338E-08"
        iyy="1.48388537589084E-06"
        iyz="-2.82528057166445E-07"
        izz="7.45927169011185E-07" />
    </inertial>
    <visual>
      <origin
        xyz="0 0 0"
        rpy="0 0 0" />
      <geometry>
        <mesh
          filename="../meshes/thumb.STL" />
      </geometry>
      <material
        name="">
        <color
          rgba="0.792156862745098 0.819607843137255 0.933333333333333 1" />
      </material>
    </visual>
    <collision>
      <origin
        xyz="0 0 0"
        rpy="0 0 0" />
      <geometry>
        <mesh
          filename="../meshes/thumb.STL" />
      </geometry>
    </collision>
  </link>
  <joint
    name="circumduction"
    type="revolute">
    <origin
      xyz="0.00370991967320959 0.0778978368943719 0.0197514136023172"
      rpy="0 0 0" />
    <parent
      link="hand_origin" />
    <child
      link="thumb" />
    <axis
      xyz="-0.229185871200052 -0.973163158458363 -0.0206713197841076" />
    <limit
      lower="-0.6"
      upper="0.1"
      effort="0"
      velocity="0" />
  </joint>
  <link
    name="thumb_abduction">
    <inertial>
      <origin
        xyz="0.0126107088267812 -0.00364765147838937 -0.00178147637971057"
        rpy="0 0 0" />
      <mass
        value="0.0264428604999541" />
      <inertia
        ixx="5.36230967445879E-06"
        ixy="-3.29750391545269E-07"
        ixz="2.99236797383711E-07"
        iyy="3.62331550830776E-06"
        iyz="-1.46942779734852E-07"
        izz="3.07527926087961E-06" />
    </inertial>
    <visual>
      <origin
        xyz="0 0 0"
        rpy="0 0 0" />
      <geometry>
        <mesh
          filename="../meshes/thumb_abduction.STL" />
      </geometry>
      <material
        name="">
        <color
          rgba="0.792156862745098 0.819607843137255 0.933333333333333 1" />
      </material>
    </visual>
    <collision>
      <origin
        xyz="0 0 0"
        rpy="0 0 0" />
      <geometry>
        <mesh
          filename="../meshes/thumb_abduction.STL" />
      </geometry>
    </collision>
  </link>
  <joint
    name="MCP_A_thumb"
    type="revolute">
    <origin
      xyz="-0.0321441107001726 -0.0225708828237391 -0.0323091303826847"
      rpy="0 0 0" />
    <parent
      link="thumb" />
    <child
      link="thumb_abduction" />
    <axis
      xyz="0.973371143108329 -0.229234852856158 0" />
    <limit
      lower="0"
      upper="2"
      effort="0"
      velocity="0" />
  </joint>
  <link
    name="thumb_inter">
    <inertial>
      <origin
        xyz="-0.00260670403491632 -0.0108791088797989 -0.0182754703997129"
        rpy="0 0 0" />
      <mass
        value="0.00887103030990217" />
      <inertia
        ixx="1.94689608711788E-06"
        ixy="-6.41099574455908E-08"
        ixz="-1.04340829712788E-07"
        iyy="1.74045324361645E-06"
        iyz="-2.4198417160809E-07"
        izz="7.3172598404725E-07" />
    </inertial>
    <visual>
      <origin
        xyz="0 0 0"
        rpy="0 0 0" />
      <geometry>
        <mesh
          filename="../meshes/thumb_inter.STL" />
      </geometry>
      <material
        name="">
        <color
          rgba="0.752941176470588 0.752941176470588 0.752941176470588 1" />
      </material>
    </visual>
    <collision>
      <origin
        xyz="0 0 0"
        rpy="0 0 0" />
      <geometry>
        <mesh
          filename="../meshes/thumb_inter.STL" />
      </geometry>
    </collision>
  </link>
  <joint
    name="PIP_thumb"
    type="revolute">
    <origin
      xyz="0.0189782823306077 -0.00884284221341614 -0.0272724744675539"
      rpy="0 0 0" />
    <parent
      link="thumb_abduction" />
    <child
      link="thumb_inter" />
    <axis
      xyz="0.222602988561972 0.945211091316152 -0.238796780414242" />
    <limit
      lower="-1.5"
      upper="0"
      effort="0"
      velocity="0" />
  </joint>
  <link
    name="thumb_distal">
    <inertial>
      <origin
        xyz="-0.00298455046406867 -0.0121349302761894 -0.0110379338988981"
        rpy="0 0 0" />
      <mass
        value="0.00502934180377221" />
      <inertia
        ixx="5.42872803612086E-07"
        ixy="-1.97867565913643E-08"
        ixz="1.53270119986316E-08"
        iyy="4.43356195986788E-07"
        iyz="-1.46613657597982E-08"
        izz="3.9885376175655E-07" />
    </inertial>
    <visual>
      <origin
        xyz="0 0 0"
        rpy="0 0 0" />
      <geometry>
        <mesh
          filename="../meshes/thumb_distal.STL" />
      </geometry>
      <material
        name="">
        <color
          rgba="0.752941176470588 0.752941176470588 0.752941176470588 1" />
      </material>
    </visual>
    <collision>
      <origin
        xyz="0 0 0"
        rpy="0 0 0" />
      <geometry>
        <mesh
          filename="../meshes/thumb_distal.STL" />
      </geometry>
    </collision>
  </link>
  <joint
    name="DIP_thumb"
    type="revolute">
    <origin
      xyz="-0.00157655337196645 -0.00669432042606979 -0.0405302424554609"
      rpy="0 0 0" />
    <parent
      link="thumb_inter" />
    <child
      link="thumb_distal" />
    <axis
      xyz="0.222602988561972 0.945211091316152 -0.238796780414242" />
    <limit
      lower="-1.5"
      upper="0"
      effort="0"
      velocity="0" />
  </joint>
  <link
    name="abduction_1">
    <inertial>
      <origin
        xyz="-6.03565114554172E-11 0.00329900174362591 -0.00786210094447506"
        rpy="0 0 0" />
      <mass
        value="0.00148234880379266" />
      <inertia
        ixx="7.97281821893678E-08"
        ixy="6.80297473863727E-17"
        ixz="3.10066213873972E-16"
        iyy="1.27500148415264E-07"
        iyz="2.46988578757295E-08"
        izz="1.27073958361039E-07" />
    </inertial>
    <visual>
      <origin
        xyz="0 0 0"
        rpy="0 0 0" />
      <geometry>
        <mesh
          filename="../meshes/abduction_1.STL" />
      </geometry>
      <material
        name="">
        <color
          rgba="1 1 1 0.35" />
      </material>
    </visual>
    <collision>
      <origin
        xyz="0 0 0"
        rpy="0 0 0" />
      <geometry>
        <mesh
          filename="../meshes/abduction_1.STL" />
      </geometry>
    </collision>
  </link>
  <joint
    name="MCP_A_1"
    type="revolute">
    <origin
      xyz="-0.017994427913583 0.110126914145522 0.0361229690938007"
      rpy="0 0 0" />
    <parent
      link="hand_origin" />
    <child
      link="abduction_1" />
    <axis
      xyz="0 0.0212365807060809 -0.999774478389959" />
    <limit
      lower="-0.471239"
      upper="0.471239"
      effort="0"
      velocity="0" />
  </joint>
  <link
    name="finger_1">
    <inertial>
      <origin
        xyz="0.0082498237798149 0.0181170112002921 0.00343576428287698"
        rpy="0 0 0" />
      <mass
        value="0.00756572549528802" />
      <inertia
        ixx="8.4474170010844E-07"
        ixy="3.86377725088552E-11"
        ixz="-2.94627501735292E-11"
        iyy="4.93966991926813E-07"
        iyz="3.80516192146476E-08"
        izz="9.34397006873227E-07" />
    </inertial>
    <visual>
      <origin
        xyz="0 0 0"
        rpy="0 0 0" />
      <geometry>
        <mesh
          filename="../meshes/finger_1.STL" />
      </geometry>
      <material
        name="">
        <color
          rgba="0.752941176470588 0.752941176470588 0.752941176470588 1" />
      </material>
    </visual>
    <collision>
      <origin
        xyz="0 0 0"
        rpy="0 0 0" />
      <geometry>
        <mesh
          filename="../meshes/finger_1.STL" />
      </geometry>
    </collision>
  </link>
  <joint
    name="MCP_1"
    type="revolute">
    <origin
      xyz="-0.00850000000000009 0.00803213992053163 -0.0132002653008772"
      rpy="0 0 0" />
    <parent
      link="abduction_1" />
    <child
      link="finger_1" />
    <axis
      xyz="-1 0 0" />
    <limit
      lower="0"
      upper="1.5"
      effort="0"
      velocity="0" />
  </joint>
  <link
    name="inter_1">
    <inertial>
      <origin
        xyz="0.00849983995903922 0.0154727081800113 0.0033885093660045"
        rpy="0 0 0" />
      <mass
        value="0.00429762211682086" />
      <inertia
        ixx="3.77003983554837E-07"
        ixy="-2.26408289885782E-11"
        ixz="1.27149646993104E-11"
        iyy="2.14354664261746E-07"
        iyz="3.75250170622433E-09"
        izz="4.03680483634736E-07" />
    </inertial>
    <visual>
      <origin
        xyz="0 0 0"
        rpy="0 0 0" />
      <geometry>
        <mesh
          filename="../meshes/inter_1.STL" />
      </geometry>
      <material
        name="">
        <color
          rgba="0.752941176470588 0.752941176470588 0.752941176470588 1" />
      </material>
    </visual>
    <collision>
      <origin
        xyz="0 0 0"
        rpy="0 0 0" />
      <geometry>
        <mesh
          filename="../meshes/inter_1.STL" />
      </geometry>
    </collision>
  </link>
  <joint
    name="PIP_1"
    type="revolute">
    <origin
      xyz="-0.000249999999998196 0.0362418248416358 0.000769826050595494"
      rpy="0 0 0" />
    <parent
      link="finger_1" />
    <child
      link="inter_1" />
    <axis
      xyz="1 0 0" />
    <limit
      lower="-1.5"
      upper="0"
      effort="0"
      velocity="0" />
  </joint>
  <link
    name="distal_1">
    <inertial>
      <origin
        xyz="0.00799960061547264 0.00964770229434871 0.00178180598420893"
        rpy="0 0 0" />
      <mass
        value="0.00510013518505954" />
      <inertia
        ixx="2.38291738236741E-07"
        ixy="-1.04544845788618E-11"
        ixz="-5.46760756747977E-12"
        iyy="1.59539752620053E-07"
        iyz="1.25482268517796E-08"
        izz="2.96910354174042E-07" />
    </inertial>
    <visual>
      <origin
        xyz="0 0 0"
        rpy="0 0 0" />
      <geometry>
        <mesh
          filename="../meshes/distal_1.STL" />
      </geometry>
      <material
        name="">
        <color
          rgba="0.752941176470588 0.752941176470588 0.752941176470588 1" />
      </material>
    </visual>
    <collision>
      <origin
        xyz="0 0 0"
        rpy="0 0 0" />
      <geometry>
        <mesh
          filename="../meshes/distal_1.STL" />
      </geometry>
    </collision>
  </link>
  <joint
    name="DIP_1"
    type="revolute">
    <origin
      xyz="0.000500000000001326 0.0331571437691609 0.000704303195227497"
      rpy="0 0 0" />
    <parent
      link="inter_1" />
    <child
      link="distal_1" />
    <axis
      xyz="-1 0 0" />
    <limit
      lower="0"
      upper="1.5"
      effort="0"
      velocity="0" />
  </joint>
  <link
    name="finger_2">
    <inertial>
      <origin
        xyz="0.00012531325550094 0.00329649322652324 -0.00786215489873041"
        rpy="0 0 0" />
      <mass
        value="0.00148234845314146" />
      <inertia
        ixx="7.98063666528832E-08"
        ixy="1.93081236062353E-09"
        ixz="1.02842182911056E-09"
        iyy="1.27422830054502E-07"
        iyz="2.46774570062047E-08"
        izz="1.27073081775977E-07" />
    </inertial>
    <visual>
      <origin
        xyz="0 0 0"
        rpy="0 0 0" />
      <geometry>
        <mesh
          filename="../meshes/finger_2.STL" />
      </geometry>
      <material
        name="">
        <color
          rgba="1 1 1 0.35" />
      </material>
    </visual>
    <collision>
      <origin
        xyz="0 0 0"
        rpy="0 0 0" />
      <geometry>
        <mesh
          filename="../meshes/finger_2.STL" />
      </geometry>
    </collision>
  </link>
  <joint
    name="MCP_A_2"
    type="revolute">
    <origin
      xyz="0.0107173222145706 0.122450540662678 0.0363847398178788"
      rpy="0 0 0" />
    <parent
      link="hand_origin" />
    <child
      link="finger_2" />
    <axis
      xyz="0 0.0212365807060816 -0.999774478389959" />
    <limit
      lower="-0.471239"
      upper="0.471239"
      effort="0"
      velocity="0" />
  </joint>
  <link
    name="proximal_2">
    <inertial>
      <origin
        xyz="0.00897092544691095 0.0177724472810517 0.00342849549497713"
        rpy="0 0 0" />
      <mass
        value="0.00756567707682998" />
      <inertia
        ixx="8.44178144929532E-07"
        ixy="-1.39574614624865E-08"
        ixz="1.56295635845723E-09"
        iyy="4.94520408441262E-07"
        iyz="3.80302615354417E-08"
        izz="9.34391055490776E-07" />
    </inertial>
    <visual>
      <origin
        xyz="0 0 0"
        rpy="0 0 0" />
      <geometry>
        <mesh
          filename="../meshes/proximal_2.STL" />
      </geometry>
      <material
        name="">
        <color
          rgba="0.752941176470588 0.752941176470588 0.752941176470588 1" />
      </material>
    </visual>
    <collision>
      <origin
        xyz="0 0 0"
        rpy="0 0 0" />
      <geometry>
        <mesh
          filename="../meshes/proximal_2.STL" />
      </geometry>
    </collision>
  </link>
  <joint
    name="MCP_2"
    type="revolute">
    <origin
      xyz="-0.00818303830411618 0.00836602304900828 -0.013193173165443"
      rpy="0 0 0" />
    <parent
      link="finger_2" />
    <child
      link="proximal_2" />
    <axis
      xyz="-0.999198892929524 0.0400106244828963 0.000849880522380277" />
    <limit
      lower="0"
      upper="1.5"
      effort="0"
      velocity="0" />
  </joint>
  <link
    name="inter_2">
    <inertial>
      <origin
        xyz="0.00911498322501283 0.0151201794009813 0.0033810098299009"
        rpy="0 0 0" />
      <mass
        value="0.00429762654170709" />
      <inertia
        ixx="3.76742559837541E-07"
        ixy="-6.52168707603763E-09"
        ixz="1.85359593820066E-10"
        iyy="2.1461699290039E-07"
        iyz="3.75136783004064E-09"
        izz="4.03680379549813E-07" />
    </inertial>
    <visual>
      <origin
        xyz="0 0 0"
        rpy="0 0 0" />
      <geometry>
        <mesh
          filename="../meshes/inter_2.STL" />
      </geometry>
      <material
        name="">
        <color
          rgba="0.752941176470588 0.752941176470588 0.752941176470588 1" />
      </material>
    </visual>
    <collision>
      <origin
        xyz="0 0 0"
        rpy="0 0 0" />
      <geometry>
        <mesh
          filename="../meshes/inter_2.STL" />
      </geometry>
    </collision>
  </link>
  <joint
    name="PIP_2"
    type="revolute">
    <origin
      xyz="0.00120091258124699 0.0362227939156274 0.000769421807633008"
      rpy="0 0 0" />
    <parent
      link="proximal_2" />
    <child
      link="inter_2" />
    <axis
      xyz="0.999198892929524 -0.0400106244828973 -0.000849880522381874" />
    <limit
      lower="-1.5"
      upper="0"
      effort="0"
      velocity="0" />
  </joint>
  <link
    name="distal_2">
    <inertial>
      <origin
        xyz="0.00838069523169022 0.00931992148693848 0.00177485560319596"
        rpy="0 0 0" />
      <mass
        value="0.00510013218958715" />
      <inertia
        ixx="2.38166089486977E-07"
        ixy="-3.14799536193671E-09"
        ixz="5.45361285750432E-10"
        iyy="1.59666615186706E-07"
        iyz="1.25386508982654E-08"
        izz="2.969102297972E-07" />
    </inertial>
    <visual>
      <origin
        xyz="0 0 0"
        rpy="0 0 0" />
      <geometry>
        <mesh
          filename="../meshes/distal_2.STL" />
      </geometry>
      <material
        name="">
        <color
          rgba="0.752941176470588 0.752941176470588 0.752941176470588 1" />
      </material>
    </visual>
    <collision>
      <origin
        xyz="0 0 0"
        rpy="0 0 0" />
      <geometry>
        <mesh
          filename="../meshes/distal_2.STL" />
      </geometry>
    </collision>
  </link>
  <joint
    name="DIP_2"
    type="revolute">
    <origin
      xyz="0.00182683604830591 0.0331105760346107 0.00070331403269689"
      rpy="0 0 0" />
    <parent
      link="inter_2" />
    <child
      link="distal_2" />
    <axis
      xyz="-0.999198892929524 0.0400106244828975 0.0008498805223819" />
    <limit
      lower="0"
      upper="1.5"
      effort="0"
      velocity="0" />
  </joint>
  <link
    name="finger_3">
    <inertial>
      <origin
        xyz="0.000330030949275095 0.00328156438950578 -0.00786247110546711"
        rpy="0 0 0" />
      <mass
        value="0.00148234857670801" />
      <inertia
        ixx="8.02705166386397E-08"
        ixy="5.06054092992584E-09"
        ixz="2.70797438328005E-09"
        iyy="1.26963903743563E-07"
        iyz="2.45500733286578E-08"
        izz="1.27067877620265E-07" />
    </inertial>
    <visual>
      <origin
        xyz="0 0 0"
        rpy="0 0 0" />
      <geometry>
        <mesh
          filename="../meshes/finger_3.STL" />
      </geometry>
      <material
        name="">
        <color
          rgba="1 1 1 0.35" />
      </material>
    </visual>
    <collision>
      <origin
        xyz="0 0 0"
        rpy="0 0 0" />
      <geometry>
        <mesh
          filename="../meshes/finger_3.STL" />
      </geometry>
    </collision>
  </link>
  <joint
    name="MCP_A_3"
    type="revolute">
    <origin
      xyz="0.0363971674161245 0.108303503158 0.0360842373443561"
      rpy="0 0 0" />
    <parent
      link="hand_origin" />
    <child
      link="finger_3" />
    <axis
      xyz="0 0.0212365807060821 -0.999774478389959" />
    <limit
      lower="-0.471239"
      upper="0.471239"
      effort="0"
      velocity="0" />
  </joint>
  <link
    name="proximal_3">
    <inertial>
      <origin
        xyz="0.0101206199308936 0.0171464620945661 0.00341516513107289"
        rpy="0 0 0" />
      <mass
        value="0.00756571118816133" />
      <inertia
        ixx="8.40870265343462E-07"
        ixy="-3.66345411294644E-08"
        ixz="4.18464805550613E-09"
        iyy="4.9784370358042E-07"
        iyz="3.78741612175703E-08"
        izz="9.34385640303218E-07" />
    </inertial>
    <visual>
      <origin
        xyz="0 0 0"
        rpy="0 0 0" />
      <geometry>
        <mesh
          filename="../meshes/proximal_3.STL" />
      </geometry>
      <material
        name="">
        <color
          rgba="0.752941176470588 0.752941176470588 0.752941176470588 1" />
      </material>
    </visual>
    <collision>
      <origin
        xyz="0 0 0"
        rpy="0 0 0" />
      <geometry>
        <mesh
          filename="../meshes/proximal_3.STL" />
      </geometry>
    </collision>
  </link>
  <joint
    name="MCP_3"
    type="revolute">
    <origin
      xyz="-0.00763582543747262 0.00888466055303554 -0.0131821565937566"
      rpy="0 0 0" />
    <parent
      link="finger_3" />
    <child
      link="proximal_3" />
    <axis
      xyz="0.994430167109535 -0.105373776763931 -0.00223828349587684" />
    <limit
      lower="-1.51"
      upper="0"
      effort="0"
      velocity="0" />
  </joint>
  <link
    name="inter_3">
    <inertial>
      <origin
        xyz="0.010090500007141 0.0144905090916585 0.00336763070074108"
        rpy="0 0 0" />
      <mass
        value="0.00429762762746428" />
      <inertia
        ixx="3.7519593306699E-07"
        ixy="-1.70571661635789E-08"
        ixz="4.69460570894858E-10"
        iyy="2.16164825785861E-07"
        iyz="3.74640847416809E-09"
        izz="4.03679590092331E-07" />
    </inertial>
    <visual>
      <origin
        xyz="0 0 0"
        rpy="0 0 0" />
      <geometry>
        <mesh
          filename="../meshes/inter_3.STL" />
      </geometry>
      <material
        name="">
        <color
          rgba="0.752941176470588 0.752941176470588 0.752941176470588 1" />
      </material>
    </visual>
    <collision>
      <origin
        xyz="0 0 0"
        rpy="0 0 0" />
      <geometry>
        <mesh
          filename="../meshes/inter_3.STL" />
      </geometry>
    </collision>
  </link>
  <joint
    name="PIP_3"
    type="revolute">
    <origin
      xyz="0.00357205350754697 0.036066307377814 0.000766097819012185"
      rpy="0 0 0" />
    <parent
      link="proximal_3" />
    <child
      link="inter_3" />
    <axis
      xyz="0.994430167109535 -0.105373776763931 -0.00223828349587577" />
    <limit
      lower="-1.51"
      upper="0"
      effort="0"
      velocity="0" />
  </joint>
  <link
    name="distal_3">
    <inertial>
      <origin
        xyz="0.00897563421257961 0.00875090520116437 0.00176279990918621"
        rpy="0 0 0" />
      <mass
        value="0.00510013056387097" />
      <inertia
        ixx="2.37421037883179E-07"
        ixy="-8.23533853624512E-09"
        ixz="1.44645220006326E-09"
        iyy="1.60413686074856E-07"
        iyz="1.24819334009582E-08"
        izz="2.96905720408619E-07" />
    </inertial>
    <visual>
      <origin
        xyz="0 0 0"
        rpy="0 0 0" />
      <geometry>
        <mesh
          filename="../meshes/distal_3.STL" />
      </geometry>
      <material
        name="">
        <color
          rgba="0.752941176470588 0.752941176470588 0.752941176470588 1" />
      </material>
    </visual>
    <collision>
      <origin
        xyz="0 0 0"
        rpy="0 0 0" />
      <geometry>
        <mesh
          filename="../meshes/distal_3.STL" />
      </geometry>
    </collision>
  </link>
  <joint
    name="DIP_3"
    type="revolute">
    <origin
      xyz="0.00399268497943315 0.0329197771308595 0.000699261202377052"
      rpy="0 0 0" />
    <parent
      link="inter_3" />
    <child
      link="distal_3" />
    <axis
      xyz="-0.994430167109535 0.105373776763931 0.00223828349587494" />
    <limit
      lower="0"
      upper="1.51"
      effort="0"
      velocity="0" />
  </joint>
  <link
    name="finger_4">
    <inertial>
      <origin
        xyz="0.000767751196163791 0.00320344521018197 -0.0078641262164754"
        rpy="0 0 0" />
      <mass
        value="0.0014823498446203" />
      <inertia
        ixx="8.26631467393603E-08"
        ixy="1.14737068715443E-08"
        ixz="6.29322279249522E-09"
        iyy="1.24598568954092E-07"
        iyz="2.38842536302794E-08"
        izz="1.27040668640534E-07" />
    </inertial>
    <visual>
      <origin
        xyz="0 0 0"
        rpy="0 0 0" />
      <geometry>
        <mesh
          filename="../meshes/finger_4.STL" />
      </geometry>
      <material
        name="">
        <color
          rgba="1 1 1 0.35" />
      </material>
    </visual>
    <collision>
      <origin
        xyz="0 0 0"
        rpy="0 0 0" />
      <geometry>
        <mesh
          filename="../meshes/finger_4.STL" />
      </geometry>
    </collision>
  </link>
  <joint
    name="MCP_A_4"
    type="revolute">
    <origin
      xyz="0.0555819236120889 0.0862672402607151 0.0356161569066215"
      rpy="0 0 0" />
    <parent
      link="hand_origin" />
    <child
      link="finger_4" />
    <axis
      xyz="0 0.0212365807060809 -0.999774478389959" />
    <limit
      lower="-0.471239"
      upper="0.471239"
      effort="0"
      velocity="0" />
  </joint>
  <link
    name="proximal_4">
    <inertial>
      <origin
        xyz="0.0124569364573015 0.0155397902630151 0.00338103793864796"
        rpy="0 0 0" />
      <mass
        value="0.00756570822288214" />
      <inertia
        ixx="8.23778196503781E-07"
        ixy="-8.31417979360036E-08"
        ixz="9.82032138736685E-09"
        iyy="5.14977360146334E-07"
        iyz="3.70599700806026E-08"
        izz="9.34342902300745E-07" />
    </inertial>
    <visual>
      <origin
        xyz="0 0 0"
        rpy="0 0 0" />
      <geometry>
        <mesh
          filename="../meshes/proximal_4.STL" />
      </geometry>
      <material
        name="">
        <color
          rgba="0.752941176470588 0.752941176470588 0.752941176470588 1" />
      </material>
    </visual>
    <collision>
      <origin
        xyz="0 0 0"
        rpy="0 0 0" />
      <geometry>
        <mesh
          filename="../meshes/proximal_4.STL" />
      </geometry>
    </collision>
  </link>
  <joint
    name="MCP_4"
    type="revolute">
    <origin
      xyz="-0.0063404 0.0098792 -0.013161"
      rpy="0 0 0" />
    <parent
      link="finger_4" />
    <child
      link="proximal_4" />
    <axis
      xyz="-0.96948 0.24513 0.0052069" />
    <limit
      lower="0"
      upper="1.51"
      effort="0"
      velocity="0" />
  </joint>
  <link
    name="inter_4">
    <inertial>
      <origin
        xyz="0.0120508795598456 0.0129148644648823 0.00333415482702171"
        rpy="0 0 0" />
      <mass
        value="0.00429762903108769" />
      <inertia
        ixx="3.67231445429123E-07"
        ixy="-3.86554454870533E-08"
        ixz="1.0965214068155E-09"
        iyy="2.24134560916859E-07"
        iyz="3.72017073153266E-09"
        izz="4.03675156344808E-07" />
    </inertial>
    <visual>
      <origin
        xyz="0 0 0"
        rpy="0 0 0" />
      <geometry>
        <mesh
          filename="../meshes/inter_4.STL" />
      </geometry>
      <material
        name="">
        <color
          rgba="0.752941176470588 0.752941176470588 0.752941176470588 1" />
      </material>
    </visual>
    <collision>
      <origin
        xyz="0 0 0"
        rpy="0 0 0" />
      <geometry>
        <mesh
          filename="../meshes/inter_4.STL" />
      </geometry>
    </collision>
  </link>
  <joint
    name="PIP_4"
    type="revolute">
    <origin
      xyz="0.00864564052563462 0.0351968599442813 0.000747629563430489"
      rpy="0 0 0" />
    <parent
      link="proximal_4" />
    <child
      link="inter_4" />
    <axis
      xyz="0.969475938482998 -0.245131174401124 -0.0052069222422588" />
    <limit
      lower="-1.51"
      upper="0"
      effort="0"
      velocity="0" />
  </joint>
  <link
    name="distal_4">
    <inertial>
      <origin
        xyz="0.0101296303824297 0.00739135593020559 0.00173395149213305"
        rpy="0 0 0" />
      <mass
        value="0.00510007434148116" />
      <inertia
        ixx="2.33586727970682E-07"
        ixy="-1.86643073977807E-08"
        ixz="3.3853548853863E-09"
        iyy="1.6425998655685E-07"
        iyz="1.21803553657867E-08"
        izz="2.96887335443029E-07" />
    </inertial>
    <visual>
      <origin
        xyz="0 0 0"
        rpy="0 0 0" />
      <geometry>
        <mesh
          filename="../meshes/distal_4.STL" />
      </geometry>
      <material
        name="">
        <color
          rgba="0.752941176470588 0.752941176470588 0.752941176470588 1" />
      </material>
    </visual>
    <collision>
      <origin
        xyz="0 0 0"
        rpy="0 0 0" />
      <geometry>
        <mesh
          filename="../meshes/distal_4.STL" />
      </geometry>
    </collision>
  </link>
  <joint
    name="DIP_4"
    type="revolute">
    <origin
      xyz="0.00861625481313492 0.0320224874858224 0.000680201540048775"
      rpy="0 0 0" />
    <parent
      link="inter_4" />
    <child
      link="distal_4" />
    <axis
      xyz="-0.969475938482998 0.245131174401124 0.00520692224225841" />
    <limit
      lower="0"
      upper="1.51"
      effort="0"
      velocity="0" />
  </joint>
</robot>